Workbook
Name _1925165: #REF!
Name _81: #REF!
Name _RR2: [12]RentRoll!$A$69:$Y$129
Name _SF1: #REF!
Name _SF2: [13]Assumptions!#REF!
Name a: #REF!
Name ACCOUNTING_2: "_($* #,##0.00_);_($* (#,##0.00);_($* " & """'-""" & "_);_(@_)"
Name AfterFee: #REF!
Name Age_Restricted_Housing_Type: [18]Dropdowns!$AW$3:$AW$6
Name AMORT_PERIOD: [19]Inputs!$I$24
Name ANALYSIS_END_DATE: [19]Inputs!$I$50
Name ANALYSIS_START: [19]Inputs!$I$14
Name Applicable_Index_Type: [18]Dropdowns!$M$3:$M$15
Name Assignment: OFFSET([21]T12!$O$18,,,COUNTA([21]T12!$O:$O),1)
Name Assumptions: #REF!
Name base: [23]Salaries!$P$4
Name baseburden: [23]Salaries!$S$134
Name baseperc: [23]Salaries!$Q$4
Name BeforeFee: #REF!
Name Begin_Clear: #REF!
Name Begin_Table: #REF!
Name bld_stories: [24]Instruction!$C$57:$C$72
Name bld_type_list: [24]Lookup!$C$805:$C$809
Name bld_type_start: [24]Lookup!$C$805
Name BlindUW: [25]ASSUMPTIONS!$C$49
Name Bond_Property_Type: [18]Dropdowns!$AT$3:$AT$5
Name Bond_Type: [18]Dropdowns!$AQ$3:$AQ$6
Name Bond_Variable_Rate_Index: [18]Dropdowns!$AY$3:$AY$12
Name Borrower_Principal_Role: [18]Dropdowns!$U$3:$U$14
Name building_total: [24]Instruction!$K$18
Name building_types: [24]Lookup!$W$493:$W$497
Name burden: [23]Salaries!$M$4
Name burden_tbl: [27]Salaries!#REF!
Name CAcct: #REF!
Name CAP_INCREMENT: '[28]Valuation Summary-Output'!#REF!
Name Capmark_fund: #REF!
Name cdsConforming: '[18]ASR Dropdowns'!$AD$3:$AD$5
Name cdsConstructionTypes: '[18]ASR Dropdowns'!$I$3:$I$11
Name cdsEntityTypes: '[18]ASR Dropdowns'!$AB$3:$AB$6
Name cdsExteriorFinishes: '[18]ASR Dropdowns'!$L$3:$L$16
Name cdsLeaseTypes: '[18]ASR Dropdowns'!$A$3:$A$8
Name cdsOpStmntColumns: [18]IandE!#REF!
Name cdsOwnershipTypes: '[18]ASR Dropdowns'!$Z$3:$Z$5
Name cdsRoofTypes: '[18]ASR Dropdowns'!$O$3:$O$16
Name cdsSeismicZones: '[18]ASR Dropdowns'!$R$3:$R$7
Name cdsYesNo: '[18]ASR Dropdowns'!$E$3:$E$5
Name cdsYesNoNA: '[18]ASR Dropdowns'!$G$3:$G$6
Name cdsYesNoPlus: '[18]ASR Dropdowns'!$C$3:$C$8
Name CHeader: #REF!
Name Clear_Range: #REF!
Name client_address: [24]Instruction!$J$10
Name client_address_2: [24]Instruction!$J$11
Name client_name: [24]Instruction!$J$9
Name Clients: [24]Lookup!$A$344:$M$468
Name climate_zone: [24]Energy_Audit_Data!$C$127
Name CommUnits: OFFSET([25]ASSUMPTIONS!$B$66,,,COUNT([25]ASSUMPTIONS!$B$66:$B$75),)
Name ConditionList: [24]Lookup!$U$583:$U$593
Name Construction_Term: [18]Dropdowns!$AV$3:$AV$5
Name Contract_Rent: '[29] Rent Roll-Input'!$G$5:$G$304
Name COST_OF_SALE: [19]Inputs!$I$49

Sheet Service Fee Calculator
B2: Assumable Loan Info | O2: New Loan Info | T2: Service Fee | U2: Matthews Split
B3: Original Loan Balance | C3: ='[29]Proforma-Input'!E113 -> 0 | O3: New Loan Balance | P3: 9700000 | S3: Year 1 | T3: =SUM(AA16:AA27) -> 9645.1116 | U3: =SUM(AB16:AB27) -> 2411.2779
B4: Existing Loan Balance | C4: ='[29]Proforma-Input'!E114 -> 0 | O4: Interest Rate | P4: 0.068 | S4: Year 2 | T4: =SUM(AA28:AA39) -> 9538.8675 | U4: =SUM(AB28:AB39) -> 2384.7169
B5: Interest Rate | C5: ='[29]Proforma-Input'!K113 -> 0 | O5: Amortization (In Years) | P5: 30 | S5: Year 3 | T5: =SUM(AA40:AA51) -> 9425.1694 | U5: =SUM(AB40:AB51) -> 2356.2923
B6: Amortization (In Years) | C6: ='[29]Proforma-Input'!K110 -> 0 | O6: Term(Years) | P6: 5 | S6: Year 4 | T6: =SUM(AA52:AA63) -> 9303.4942 | U6: =SUM(AB52:AB63) -> 2325.8736
B7: Remaining Term in Months | C7: ='[29]Optimistic Return Calculation'!E54 -> 0 | O7: Monthly Payment | P7: =PMT(P4/12,P5*12,-P3,0) -> 63236.743 | S7: Year 5 | T7: =SUM(AA64:AA75) -> 9173.2823 | U7: =SUM(AB64:AB75) -> 2293.3206
B8: Monthly Payment | C8: ='[29]Proforma-Input'!K114 -> 0 | N8: Yes | O8: I/O(Monthly): | P8: 0 | Q8: Total(Term)
B9: Final Payment Date | C9: =IFERROR('[29]Proforma-Input'!E111+(C7*30),"-") -> - | O9: Service Fee | P9: 0.001 | Q9: =SUMIFS($AA$15:$AA$374, $Q$15:$Q$374, "<=" & 12 * $P$6) -> 47135.01
B10: IO: | C10: =IFERROR('[29]Proforma-Input'!K116*12,"-") -> 0 | D10: =IF(C10>0,"Yes","No") -> No | O10: Matthews Split | P10: 0.25 | Q10: =SUMIFS($AB$15:$AB$374, $Q$15:$Q$374, "<=" & 12 * $P$6) -> 11783.753
C13: Assumable Loan Table | P13: Loan Calculations
B14: Month | C14: Year | D14: # of Months | E14: Month/Year | F14: Beg. Balance | G14: Payment | H14: Rate | I14: Interest | J14: Principal | K14: End Balance | L14: Interest/Year | M14: Principal/Year | O14: Month | P14: Year | Q14: # of Months | R14: Month/Year | S14: Beg. Balance | T14: Payment | U14: Rate | V14: Interest | W14: Principal | X14: End Balance | Y14: Cumulative Interest | Z14: Cumulative Principal | AA14: Service Fee | AB14: Matthews Split | AC14: Interest/Year | AD14: Principal/Year | AF14: Input Data
B15: ='[29]Proforma-Input'!$E$111 -> - | C15: 1 | D15: 1 | E15: 1 | F15: =IF('[29]Proforma-Input'!$C$108="Yes",$C$4,) -> 0 | G15: =IF(AND($D$10="Yes",D15<=$C$10),I15,IF(F15>0,$C$8,)) -> 0 | H15: =IF('[29]Proforma-Input'!$C$108="Yes",C5,) -> 0 | I15: =(H15/12)*F15 -> 0 | J15: =IF(D15=$C$7,0,G15-I15) -> 0 | K15: =IFERROR(F15-J15,) -> 0 | L15: =IF(C15>0,SUM(I15:I26),"-") -> 0 | M15: =IF(C15>0,SUM(J15:J26),"-") -> 0 | O15: =NOW() -> 45933.485 | P15: 1 | Q15: =IF(S15>0,1,) -> 1 | R15: 1 | S15: =IF('[29]Proforma-Input'!$C$108="No",$P$3,IF(AF15="True",$P$3,)) -> 9700000 | T15: =IF(AND($N$8="Yes",Q15<=$P$8),V15,IF(S15>0,$P$7,)) -> 63236.743 | U15: =$P$4 -> 0.068 | V15: =IF(S15>0,U15/12*S15,0) -> 54966.667 | W15: =T15-V15 -> 8270.0766 | X15: =S15-W15 -> 9691729.9 | Y15: =IF(Q15=1,V15,Y14+V15) -> 54966.667 | Z15: =IF(Q15=1,W15,Z14+W15) -> 8270.0766 | AA15: =$P$9*S15/12 -> 808.33333 | AB15: =$P$10*AA15 -> 202.08333 | AC15: =IF(P15>0,SUM(V15:V26),"-") -> 656447.82 | AD15: =IF(P15>0,SUM(W15:W26),"-") -> 102393.1 | AF15: =IF('[29]Proforma-Input'!$C$108="Yes",MONTH(O15)&YEAR(O15)=MONTH($C$9)&YEAR($C$9),0) -> 0 | AG15: 1
B16: =IFERROR(DATE(YEAR(B15),MONTH(B15)+1,DAY(B15)),"-") -> - | D16: 2 | E16: =1+E15 -> 2 | F16: =IFERROR(IF(B16<$C$9,IF('[29]Proforma-Input'!$C$108="Yes",K15,K15),0),) -> 0 | G16: =IFERROR(IF(D16=$C$7,K15,IF(AND($D$10="Yes",D16<=$C$10),I16,IF(F16>0,$C$8,))),) -> 0 | H16: =IFERROR(IF(B16<$C$9,IF('[29]Proforma-Input'!$C$108="Yes",H15,),0),) -> 0 | I16: =(H16/12)*F16 -> 0 | J16: =IF(D16=$C$7,0,G16-I16) -> 0 | K16: =IFERROR(F16-J16,) -> 0 | L16: =IF(C16>0,SUM(I16:I27),"-") -> - | M16: =IF(C16>0,SUM(J16:J27),"-") -> - | O16: =IFERROR(DATE(YEAR(O15),MONTH(O15)+1,DAY(O15)),"-") -> 45964 | Q16: =IF(S16>0,1+Q15,) -> 2 | R16: =1+R15 -> 2 | S16: =IF('[29]Proforma-Input'!$C$108="No",X15,IF(AF16=TRUE,$P$3,X15)) -> 9691729.9 | T16: =IF(AND($N$8="Yes",Q16<=$P$8),V16,IF(S16>0,$P$7,)) -> 63236.743 | U16: =$P$4 -> 0.068 | V16: =IF(S16>0,U16/12*S16,0) -> 54919.803 | W16: =T16-V16 -> 8316.9404 | X16: =S16-W16 -> 9683413 | Y16: =IF(Q16=1,V16,Y15+V16) -> 109886.47 | Z16: =IF(Q16=1,W16,Z15+W16) -> 16587.017 | AA16: =$P$9*S16/12 -> 807.64416 | AB16: =$P$10*AA16 -> 201.91104 | AC16: =IF(P16>0,SUM(V16:V27),"-") -> - | AD16: =IF(P16>0,SUM(W16:W27),"-") -> - | AF16: =IF('[29]Proforma-Input'!$C$108="Yes",MONTH(O16)&YEAR(O16)=MONTH($C$9)&YEAR($C$9),0) -> 0 | AG16: 1
B17: =IFERROR(DATE(YEAR(B16),MONTH(B16)+1,DAY(B16)),"-") -> - | D17: 3 | E17: =1+E16 -> 3 | F17: =IFERROR(IF(B17<$C$9,IF('[29]Proforma-Input'!$C$108="Yes",K16,K16),0),) -> 0 | G17: =IFERROR(IF(D17=$C$7,K16,IF(AND($D$10="Yes",D17<=$C$10),I17,IF(F17>0,$C$8,))),) -> 0 | H17: =IFERROR(IF(B17<$C$9,IF('[29]Proforma-Input'!$C$108="Yes",H16,),0),) -> 0 | I17: =(H17/12)*F17 -> 0 | J17: =IF(D17=$C$7,0,G17-I17) -> 0 | K17: =IFERROR(F17-J17,) -> 0 | L17: =IF(C17>0,SUM(I17:I28),"-") -> - | M17: =IF(C17>0,SUM(J17:J28),"-") -> - | O17: =IFERROR(DATE(YEAR(O16),MONTH(O16)+1,DAY(O16)),"-") -> 45994 | Q17: =IF(S17>0,1+Q16,) -> 3 | R17: =1+R16 -> 3 | S17: =IF('[29]Proforma-Input'!$C$108="No",X16,IF(AF17=TRUE,$P$3,X16)) -> 9683413 | T17: =IF(AND($N$8="Yes",Q17<=$P$8),V17,IF(S17>0,$P$7,)) -> 63236.743 | U17: =$P$4 -> 0.068 | V17: =IF(S17>0,U17/12*S17,0) -> 54872.674 | W17: =T17-V17 -> 8364.0697 | X17: =S17-W17 -> 9675048.9 | Y17: =IF(Q17=1,V17,Y16+V17) -> 164759.14 | Z17: =IF(Q17=1,W17,Z16+W17) -> 24951.087 | AA17: =$P$9*S17/12 -> 806.95108 | AB17: =$P$10*AA17 -> 201.73777 | AC17: =IF(P17>0,SUM(V17:V28),"-") -> - | AD17: =IF(P17>0,SUM(W17:W28),"-") -> - | AF17: =IF('[29]Proforma-Input'!$C$108="Yes",MONTH(O17)&YEAR(O17)=MONTH($C$9)&YEAR($C$9),0) -> 0 | AG17: 1
B18: =IFERROR(DATE(YEAR(B17),MONTH(B17)+1,DAY(B17)),"-") -> - | D18: 4 | E18: =1+E17 -> 4 | F18: =IFERROR(IF(B18<$C$9,IF('[29]Proforma-Input'!$C$108="Yes",K17,K17),0),) -> 0 | G18: =IFERROR(IF(D18=$C$7,K17,IF(AND($D$10="Yes",D18<=$C$10),I18,IF(F18>0,$C$8,))),) -> 0 | H18: =IFERROR(IF(B18<$C$9,IF('[29]Proforma-Input'!$C$108="Yes",H17,),0),) -> 0 | I18: =(H18/12)*F18 -> 0 | J18: =IF(D18=$C$7,0,G18-I18) -> 0 | K18: =IFERROR(F18-J18,) -> 0 | L18: =IF(C18>0,SUM(I18:I29),"-") -> - | M18: =IF(C18>0,SUM(J18:J29),"-") -> - | O18: =IFERROR(DATE(YEAR(O17),MONTH(O17)+1,DAY(O17)),"-") -> 46025 | Q18: =IF(S18>0,1+Q17,) -> 4 | R18: =1+R17 -> 4 | S18: =IF('[29]Proforma-Input'!$C$108="No",X17,IF(AF18=TRUE,$P$3,X17)) -> 9675048.9 | T18: =IF(AND($N$8="Yes",Q18<=$P$8),V18,IF(S18>0,$P$7,)) -> 63236.743 | U18: =$P$4 -> 0.068 | V18: =IF(S18>0,U18/12*S18,0) -> 54825.277 | W18: =T18-V18 -> 8411.4661 | X18: =S18-W18 -> 9666637.4 | Y18: =IF(Q18=1,V18,Y17+V18) -> 219584.42 | Z18: =IF(Q18=1,W18,Z17+W18) -> 33362.553 | AA18: =$P$9*S18/12 -> 806.25408 | AB18: =$P$10*AA18 -> 201.56352 | AC18: =IF(P18>0,SUM(V18:V29),"-") -> - | AD18: =IF(P18>0,SUM(W18:W29),"-") -> - | AF18: =IF('[29]Proforma-Input'!$C$108="Yes",MONTH(O18)&YEAR(O18)=MONTH($C$9)&YEAR($C$9),0) -> 0 | AG18: 1
B19: =IFERROR(DATE(YEAR(B18),MONTH(B18)+1,DAY(B18)),"-") -> - | D19: 5 | E19: =1+E18 -> 5 | F19: =IFERROR(IF(B19<$C$9,IF('[29]Proforma-Input'!$C$108="Yes",K18,K18),0),) -> 0 | G19: =IFERROR(IF(D19=$C$7,K18,IF(AND($D$10="Yes",D19<=$C$10),I19,IF(F19>0,$C$8,))),) -> 0 | H19: =IFERROR(IF(B19<$C$9,IF('[29]Proforma-Input'!$C$108="Yes",H18,),0),) -> 0 | I19: =(H19/12)*F19 -> 0 | J19: =IF(D19=$C$7,0,G19-I19) -> 0 | K19: =IFERROR(F19-J19,) -> 0 | L19: =IF(C19>0,SUM(I19:I30),"-") -> - | M19: =IF(C19>0,SUM(J19:J30),"-") -> - | O19: =IFERROR(DATE(YEAR(O18),MONTH(O18)+1,DAY(O18)),"-") -> 46056 | Q19: =IF(S19>0,1+Q18,) -> 5 | R19: =1+R18 -> 5 | S19: =IF('[29]Proforma-Input'!$C$108="No",X18,IF(AF19=TRUE,$P$3,X18)) -> 9666637.4 | T19: =IF(AND($N$8="Yes",Q19<=$P$8),V19,IF(S19>0,$P$7,)) -> 63236.743 | U19: =$P$4 -> 0.068 | V19: =IF(S19>0,U19/12*S19,0) -> 54777.612 | W19: =T19-V19 -> 8459.1311 | X19: =S19-W19 -> 9658178.3 | Y19: =IF(Q19=1,V19,Y18+V19) -> 274362.03 | Z19: =IF(Q19=1,W19,Z18+W19) -> 41821.684 | AA19: =$P$9*S19/12 -> 805.55312 | AB19: =$P$10*AA19 -> 201.38828 | AC19: =IF(P19>0,SUM(V19:V30),"-") -> - | AD19: =IF(P19>0,SUM(W19:W30),"-") -> - | AF19: =IF('[29]Proforma-Input'!$C$108="Yes",MONTH(O19)&YEAR(O19)=MONTH($C$9)&YEAR($C$9),0) -> 0 | AG19: 1
B20: =IFERROR(DATE(YEAR(B19),MONTH(B19)+1,DAY(B19)),"-") -> - | D20: 6 | E20: =1+E19 -> 6 | F20: =IFERROR(IF(B20<$C$9,IF('[29]Proforma-Input'!$C$108="Yes",K19,K19),0),) -> 0 | G20: =IFERROR(IF(D20=$C$7,K19,IF(AND($D$10="Yes",D20<=$C$10),I20,IF(F20>0,$C$8,))),) -> 0 | H20: =IFERROR(IF(B20<$C$9,IF('[29]Proforma-Input'!$C$108="Yes",H19,),0),) -> 0 | I20: =(H20/12)*F20 -> 0 | J20: =IF(D20=$C$7,0,G20-I20) -> 0 | K20: =IFERROR(F20-J20,) -> 0 | L20: =IF(C20>0,SUM(I20:I31),"-") -> - | M20: =IF(C20>0,SUM(J20:J31),"-") -> - | O20: =IFERROR(DATE(YEAR(O19),MONTH(O19)+1,DAY(O19)),"-") -> 46084 | Q20: =IF(S20>0,1+Q19,) -> 6 | R20: =1+R19 -> 6 | S20: =IF('[29]Proforma-Input'!$C$108="No",X19,IF(AF20=TRUE,$P$3,X19)) -> 9658178.3 | T20: =IF(AND($N$8="Yes",Q20<=$P$8),V20,IF(S20>0,$P$7,)) -> 63236.743 | U20: =$P$4 -> 0.068 | V20: =IF(S20>0,U20/12*S20,0) -> 54729.677 | W20: =T20-V20 -> 8507.0661 | X20: =S20-W20 -> 9649671.3 | Y20: =IF(Q20=1,V20,Y19+V20) -> 329091.71 | Z20: =IF(Q20=1,W20,Z19+W20) -> 50328.75 | AA20: =$P$9*S20/12 -> 804.84819 | AB20: =$P$10*AA20 -> 201.21205 | AC20: =IF(P20>0,SUM(V20:V31),"-") -> - | AD20: =IF(P20>0,SUM(W20:W31),"-") -> - | AF20: =IF('[29]Proforma-Input'!$C$108="Yes",MONTH(O20)&YEAR(O20)=MONTH($C$9)&YEAR($C$9),0) -> 0 | AG20: 1
B21: =IFERROR(DATE(YEAR(B20),MONTH(B20)+1,DAY(B20)),"-") -> - | D21: 7 | E21: =1+E20 -> 7 | F21: =IFERROR(IF(B21<$C$9,IF('[29]Proforma-Input'!$C$108="Yes",K20,K20),0),) -> 0 | G21: =IFERROR(IF(D21=$C$7,K20,IF(AND($D$10="Yes",D21<=$C$10),I21,IF(F21>0,$C$8,))),) -> 0 | H21: =IFERROR(IF(B21<$C$9,IF('[29]Proforma-Input'!$C$108="Yes",H20,),0),) -> 0 | I21: =(H21/12)*F21 -> 0 | J21: =IF(D21=$C$7,0,G21-I21) -> 0 | K21: =IFERROR(F21-J21,) -> 0 | L21: =IF(C21>0,SUM(I21:I32),"-") -> - | M21: =IF(C21>0,SUM(J21:J32),"-") -> - | O21: =IFERROR(DATE(YEAR(O20),MONTH(O20)+1,DAY(O20)),"-") -> 46115 | Q21: =IF(S21>0,1+Q20,) -> 7 | R21: =1+R20 -> 7 | S21: =IF('[29]Proforma-Input'!$C$108="No",X20,IF(AF21=TRUE,$P$3,X20)) -> 9649671.3 | T21: =IF(AND($N$8="Yes",Q21<=$P$8),V21,IF(S21>0,$P$7,)) -> 63236.743 | U21: =$P$4 -> 0.068 | V21: =IF(S21>0,U21/12*S21,0) -> 54681.47 | W21: =T21-V21 -> 8555.2728 | X21: =S21-W21 -> 9641116 | Y21: =IF(Q21=1,V21,Y20+V21) -> 383773.18 | Z21: =IF(Q21=1,W21,Z20+W21) -> 58884.023 | AA21: =$P$9*S21/12 -> 804.13927 | AB21: =$P$10*AA21 -> 201.03482 | AC21: =IF(P21>0,SUM(V21:V32),"-") -> - | AD21: =IF(P21>0,SUM(W21:W32),"-") -> - | AF21: =IF('[29]Proforma-Input'!$C$108="Yes",MONTH(O21)&YEAR(O21)=MONTH($C$9)&YEAR($C$9),0) -> 0 | AG21: 1
B22: =IFERROR(DATE(YEAR(B21),MONTH(B21)+1,DAY(B21)),"-") -> - | D22: 8 | E22: =1+E21 -> 8 | F22: =IFERROR(IF(B22<$C$9,IF('[29]Proforma-Input'!$C$108="Yes",K21,K21),0),) -> 0 | G22: =IFERROR(IF(D22=$C$7,K21,IF(AND($D$10="Yes",D22<=$C$10),I22,IF(F22>0,$C$8,))),) -> 0 | H22: =IFERROR(IF(B22<$C$9,IF('[29]Proforma-Input'!$C$108="Yes",H21,),0),) -> 0 | I22: =(H22/12)*F22 -> 0 | J22: =IF(D22=$C$7,0,G22-I22) -> 0 | K22: =IFERROR(F22-J22,) -> 0 | L22: =IF(C22>0,SUM(I22:I33),"-") -> - | M22: =IF(C22>0,SUM(J22:J33),"-") -> - | O22: =IFERROR(DATE(YEAR(O21),MONTH(O21)+1,DAY(O21)),"-") -> 46145 | Q22: =IF(S22>0,1+Q21,) -> 8 | R22: =1+R21 -> 8 | S22: =IF('[29]Proforma-Input'!$C$108="No",X21,IF(AF22=TRUE,$P$3,X21)) -> 9641116 | T22: =IF(AND($N$8="Yes",Q22<=$P$8),V22,IF(S22>0,$P$7,)) -> 63236.743 | U22: =$P$4 -> 0.068 | V22: =IF(S22>0,U22/12*S22,0) -> 54632.991 | W22: =T22-V22 -> 8603.7527 | X22: =S22-W22 -> 9632512.2 | Y22: =IF(Q22=1,V22,Y21+V22) -> 438406.17 | Z22: =IF(Q22=1,W22,Z21+W22) -> 67487.775 | AA22: =$P$9*S22/12 -> 803.42633 | AB22: =$P$10*AA22 -> 200.85658 | AC22: =IF(P22>0,SUM(V22:V33),"-") -> - | AD22: =IF(P22>0,SUM(W22:W33),"-") -> - | AF22: =IF('[29]Proforma-Input'!$C$108="Yes",MONTH(O22)&YEAR(O22)=MONTH($C$9)&YEAR($C$9),0) -> 0 | AG22: 1
B23: =IFERROR(DATE(YEAR(B22),MONTH(B22)+1,DAY(B22)),"-") -> - | D23: 9 | E23: =1+E22 -> 9 | F23: =IFERROR(IF(B23<$C$9,IF('[29]Proforma-Input'!$C$108="Yes",K22,K22),0),) -> 0 | G23: =IFERROR(IF(D23=$C$7,K22,IF(AND($D$10="Yes",D23<=$C$10),I23,IF(F23>0,$C$8,))),) -> 0 | H23: =IFERROR(IF(B23<$C$9,IF('[29]Proforma-Input'!$C$108="Yes",H22,),0),) -> 0 | I23: =(H23/12)*F23 -> 0 | J23: =IF(D23=$C$7,0,G23-I23) -> 0 | K23: =IFERROR(F23-J23,) -> 0 | L23: =IF(C23>0,SUM(I23:I34),"-") -> - | M23: =IF(C23>0,SUM(J23:J34),"-") -> - | O23: =IFERROR(DATE(YEAR(O22),MONTH(O22)+1,DAY(O22)),"-") -> 46176 | Q23: =IF(S23>0,1+Q22,) -> 9 | R23: =1+R22 -> 9 | S23: =IF('[29]Proforma-Input'!$C$108="No",X22,IF(AF23=TRUE,$P$3,X22)) -> 9632512.2 | T23: =IF(AND($N$8="Yes",Q23<=$P$8),V23,IF(S23>0,$P$7,)) -> 63236.743 | U23: =$P$4 -> 0.068 | V23: =IF(S23>0,U23/12*S23,0) -> 54584.236 | W23: =T23-V23 -> 8652.5073 | X23: =S23-W23 -> 9623859.7 | Y23: =IF(Q23=1,V23,Y22+V23) -> 492990.41 | Z23: =IF(Q23=1,W23,Z22+W23) -> 76140.283 | AA23: =$P$9*S23/12 -> 802.70935 | AB23: =$P$10*AA23 -> 200.67734 | AC23: =IF(P23>0,SUM(V23:V34),"-") -> - | AD23: =IF(P23>0,SUM(W23:W34),"-") -> - | AF23: =IF('[29]Proforma-Input'!$C$108="Yes",MONTH(O23)&YEAR(O23)=MONTH($C$9)&YEAR($C$9),0) -> 0 | AG23: 1
B24: =IFERROR(DATE(YEAR(B23),MONTH(B23)+1,DAY(B23)),"-") -> - | D24: 10 | E24: =1+E23 -> 10 | F24: =IFERROR(IF(B24<$C$9,IF('[29]Proforma-Input'!$C$108="Yes",K23,K23),0),) -> 0 | G24: =IFERROR(IF(D24=$C$7,K23,IF(AND($D$10="Yes",D24<=$C$10),I24,IF(F24>0,$C$8,))),) -> 0 | H24: =IFERROR(IF(B24<$C$9,IF('[29]Proforma-Input'!$C$108="Yes",H23,),0),) -> 0 | I24: =(H24/12)*F24 -> 0 | J24: =IF(D24=$C$7,0,G24-I24) -> 0 | K24: =IFERROR(F24-J24,) -> 0 | L24: =IF(C24>0,SUM(I24:I35),"-") -> - | M24: =IF(C24>0,SUM(J24:J35),"-") -> - | O24: =IFERROR(DATE(YEAR(O23),MONTH(O23)+1,DAY(O23)),"-") -> 46206 | Q24: =IF(S24>0,1+Q23,) -> 10 | R24: =1+R23 -> 10 | S24: =IF('[29]Proforma-Input'!$C$108="No",X23,IF(AF24=TRUE,$P$3,X23)) -> 9623859.7 | T24: =IF(AND($N$8="Yes",Q24<=$P$8),V24,IF(S24>0,$P$7,)) -> 63236.743 | U24: =$P$4 -> 0.068 | V24: =IF(S24>0,U24/12*S24,0) -> 54535.205 | W24: =T24-V24 -> 8701.5382 | X24: =S24-W24 -> 9615158.2 | Y24: =IF(Q24=1,V24,Y23+V24) -> 547525.61 | Z24: =IF(Q24=1,W24,Z23+W24) -> 84841.821 | AA24: =$P$9*S24/12 -> 801.98831 | AB24: =$P$10*AA24 -> 200.49708 | AC24: =IF(P24>0,SUM(V24:V35),"-") -> - | AD24: =IF(P24>0,SUM(W24:W35),"-") -> - | AF24: =IF('[29]Proforma-Input'!$C$108="Yes",MONTH(O24)&YEAR(O24)=MONTH($C$9)&YEAR($C$9),0) -> 0 | AG24: 1
B25: =IFERROR(DATE(YEAR(B24),MONTH(B24)+1,DAY(B24)),"-") -> - | D25: 11 | E25: =1+E24 -> 11 | F25: =IFERROR(IF(B25<$C$9,IF('[29]Proforma-Input'!$C$108="Yes",K24,K24),0),) -> 0 | G25: =IFERROR(IF(D25=$C$7,K24,IF(AND($D$10="Yes",D25<=$C$10),I25,IF(F25>0,$C$8,))),) -> 0 | H25: =IFERROR(IF(B25<$C$9,IF('[29]Proforma-Input'!$C$108="Yes",H24,),0),) -> 0 | I25: =(H25/12)*F25 -> 0 | J25: =IF(D25=$C$7,0,G25-I25) -> 0 | K25: =IFERROR(F25-J25,) -> 0 | L25: =IF(C25>0,SUM(I25:I36),"-") -> - | M25: =IF(C25>0,SUM(J25:J36),"-") -> - | O25: =IFERROR(DATE(YEAR(O24),MONTH(O24)+1,DAY(O24)),"-") -> 46237 | Q25: =IF(S25>0,1+Q24,) -> 11 | R25: =1+R24 -> 11 | S25: =IF('[29]Proforma-Input'!$C$108="No",X24,IF(AF25=TRUE,$P$3,X24)) -> 9615158.2 | T25: =IF(AND($N$8="Yes",Q25<=$P$8),V25,IF(S25>0,$P$7,)) -> 63236.743 | U25: =$P$4 -> 0.068 | V25: =IF(S25>0,U25/12*S25,0) -> 54485.896 | W25: =T25-V25 -> 8750.8469 | X25: =S25-W25 -> 9606407.3 | Y25: =IF(Q25=1,V25,Y24+V25) -> 602011.51 | Z25: =IF(Q25=1,W25,Z24+W25) -> 93592.668 | AA25: =$P$9*S25/12 -> 801.26318 | AB25: =$P$10*AA25 -> 200.3158 | AC25: =IF(P25>0,SUM(V25:V36),"-") -> - | AD25: =IF(P25>0,SUM(W25:W36),"-") -> - | AF25: =IF('[29]Proforma-Input'!$C$108="Yes",MONTH(O25)&YEAR(O25)=MONTH($C$9)&YEAR($C$9),0) -> 0 | AG25: 1
B26: =IFERROR(DATE(YEAR(B25),MONTH(B25)+1,DAY(B25)),"-") -> - | D26: 12 | E26: =1+E25 -> 12 | F26: =IFERROR(IF(B26<$C$9,IF('[29]Proforma-Input'!$C$108="Yes",K25,K25),0),) -> 0 | G26: =IFERROR(IF(D26=$C$7,K25,IF(AND($D$10="Yes",D26<=$C$10),I26,IF(F26>0,$C$8,))),) -> 0 | H26: =IFERROR(IF(B26<$C$9,IF('[29]Proforma-Input'!$C$108="Yes",H25,),0),) -> 0 | I26: =(H26/12)*F26 -> 0 | J26: =IF(D26=$C$7,0,G26-I26) -> 0 | K26: =IFERROR(F26-J26,) -> 0 | L26: =IF(C26>0,SUM(I26:I37),"-") -> - | M26: =IF(C26>0,SUM(J26:J37),"-") -> - | O26: =IFERROR(DATE(YEAR(O25),MONTH(O25)+1,DAY(O25)),"-") -> 46268 | Q26: =IF(S26>0,1+Q25,) -> 12 | R26: =1+R25 -> 12 | S26: =IF('[29]Proforma-Input'!$C$108="No",X25,IF(AF26=TRUE,$P$3,X25)) -> 9606407.3 | T26: =IF(AND($N$8="Yes",Q26<=$P$8),V26,IF(S26>0,$P$7,)) -> 63236.743 | U26: =$P$4 -> 0.068 | V26: =IF(S26>0,U26/12*S26,0) -> 54436.308 | W26: =T26-V26 -> 8800.435 | X26: =S26-W26 -> 9597606.9 | Y26: =IF(Q26=1,V26,Y25+V26) -> 656447.82 | Z26: =IF(Q26=1,W26,Z25+W26) -> 102393.1 | AA26: =$P$9*S26/12 -> 800.53394 | AB26: =$P$10*AA26 -> 200.13349 | AC26: =IF(P26>0,SUM(V26:V37),"-") -> - | AD26: =IF(P26>0,SUM(W26:W37),"-") -> - | AF26: =IF('[29]Proforma-Input'!$C$108="Yes",MONTH(O26)&YEAR(O26)=MONTH($C$9)&YEAR($C$9),0) -> 0 | AG26: 1
B27: =IFERROR(DATE(YEAR(B26),MONTH(B26)+1,DAY(B26)),"-") -> - | C27: 2 | D27: 13 | E27: 1 | F27: =IFERROR(IF(B27<$C$9,IF('[29]Proforma-Input'!$C$108="Yes",K26,K26),0),) -> 0 | G27: =IFERROR(IF(D27=$C$7,K26,IF(AND($D$10="Yes",D27<=$C$10),I27,IF(F27>0,$C$8,))),) -> 0 | H27: =IFERROR(IF(B27<$C$9,IF('[29]Proforma-Input'!$C$108="Yes",H26,),0),) -> 0 | I27: =(H27/12)*F27 -> 0 | J27: =IF(D27=$C$7,0,G27-I27) -> 0 | K27: =IFERROR(F27-J27,) -> 0 | L27: =IF(C27>0,SUM(I27:I38),"-") -> 0 | M27: =IF(C27>0,SUM(J27:J38),"-") -> 0 | O27: =IFERROR(DATE(YEAR(O26),MONTH(O26)+1,DAY(O26)),"-") -> 46298 | P27: 2 | Q27: =IF(S27>0,1+Q26,) -> 13 | R27: 1 | S27: =IF('[29]Proforma-Input'!$C$108="No",X26,IF(AF27=TRUE,$P$3,X26)) -> 9597606.9 | T27: =IF(AND($N$8="Yes",Q27<=$P$8),V27,IF(S27>0,$P$7,)) -> 63236.743 | U27: =$P$4 -> 0.068 | V27: =IF(S27>0,U27/12*S27,0) -> 54386.439 | W27: =T27-V27 -> 8850.3042 | X27: =S27-W27 -> 9588756.6 | Y27: =IF(Q27=1,V27,Y26+V27) -> 710834.26 | Z27: =IF(Q27=1,W27,Z26+W27) -> 111243.41 | AA27: =$P$9*S27/12 -> 799.80057 | AB27: =$P$10*AA27 -> 199.95014 | AC27: =IF(P27>0,SUM(V27:V38),"-") -> 649263.93 | AD27: =IF(P27>0,SUM(W27:W38),"-") -> 109576.99 | AF27: =IF('[29]Proforma-Input'!$C$108="Yes",MONTH(O27)&YEAR(O27)=MONTH($C$9)&YEAR($C$9),0) -> 0 | AG27: 2
B28: =IFERROR(DATE(YEAR(B27),MONTH(B27)+1,DAY(B27)),"-") -> - | D28: 14 | E28: =1+E27 -> 2 | F28: =IFERROR(IF(B28<$C$9,IF('[29]Proforma-Input'!$C$108="Yes",K27,K27),0),) -> 0 | G28: =IFERROR(IF(D28=$C$7,K27,IF(AND($D$10="Yes",D28<=$C$10),I28,IF(F28>0,$C$8,))),) -> 0 | H28: =IFERROR(IF(B28<$C$9,IF('[29]Proforma-Input'!$C$108="Yes",H27,),0),) -> 0 | I28: =(H28/12)*F28 -> 0 | J28: =IF(D28=$C$7,0,G28-I28) -> 0 | K28: =IFERROR(F28-J28,) -> 0 | L28: =IF(C28>0,SUM(I28:I39),"-") -> - | M28: =IF(C28>0,SUM(J28:J39),"-") -> - | O28: =IFERROR(DATE(YEAR(O27),MONTH(O27)+1,DAY(O27)),"-") -> 46329 | Q28: =IF(S28>0,1+Q27,) -> 14 | R28: =1+R27 -> 2 | S28: =IF('[29]Proforma-Input'!$C$108="No",X27,IF(AF28=TRUE,$P$3,X27)) -> 9588756.6 | T28: =IF(AND($N$8="Yes",Q28<=$P$8),V28,IF(S28>0,$P$7,)) -> 63236.743 | U28: =$P$4 -> 0.068 | V28: =IF(S28>0,U28/12*S28,0) -> 54336.287 | W28: =T28-V28 -> 8900.4559 | X28: =S28-W28 -> 9579856.1 | Y28: =IF(Q28=1,V28,Y27+V28) -> 765170.54 | Z28: =IF(Q28=1,W28,Z27+W28) -> 120143.86 | AA28: =$P$9*S28/12 -> 799.06305 | AB28: =$P$10*AA28 -> 199.76576 | AC28: =IF(P28>0,SUM(V28:V39),"-") -> - | AD28: =IF(P28>0,SUM(W28:W39),"-") -> - | AF28: =IF('[29]Proforma-Input'!$C$108="Yes",MONTH(O28)&YEAR(O28)=MONTH($C$9)&YEAR($C$9),0) -> 0 | AG28: 2
B29: =IFERROR(DATE(YEAR(B28),MONTH(B28)+1,DAY(B28)),"-") -> - | D29: 15 | E29: =1+E28 -> 3 | F29: =IFERROR(IF(B29<$C$9,IF('[29]Proforma-Input'!$C$108="Yes",K28,K28),0),) -> 0 | G29: =IFERROR(IF(D29=$C$7,K28,IF(AND($D$10="Yes",D29<=$C$10),I29,IF(F29>0,$C$8,))),) -> 0 | H29: =IFERROR(IF(B29<$C$9,IF('[29]Proforma-Input'!$C$108="Yes",H28,),0),) -> 0 | I29: =(H29/12)*F29 -> 0 | J29: =IF(D29=$C$7,0,G29-I29) -> 0 | K29: =IFERROR(F29-J29,) -> 0 | L29: =IF(C29>0,SUM(I29:I40),"-") -> - | M29: =IF(C29>0,SUM(J29:J40),"-") -> - | O29: =IFERROR(DATE(YEAR(O28),MONTH(O28)+1,DAY(O28)),"-") -> 46359 | Q29: =IF(S29>0,1+Q28,) -> 15 | R29: =1+R28 -> 3 | S29: =IF('[29]Proforma-Input'!$C$108="No",X28,IF(AF29=TRUE,$P$3,X28)) -> 9579856.1 | T29: =IF(AND($N$8="Yes",Q29<=$P$8),V29,IF(S29>0,$P$7,)) -> 63236.743 | U29: =$P$4 -> 0.068 | V29: =IF(S29>0,U29/12*S29,0) -> 54285.851 | W29: =T29-V29 -> 8950.8918 | X29: =S29-W29 -> 9570905.2 | Y29: =IF(Q29=1,V29,Y28+V29) -> 819456.39 | Z29: =IF(Q29=1,W29,Z28+W29) -> 129094.75 | AA29: =$P$9*S29/12 -> 798.32134 | AB29: =$P$10*AA29 -> 199.58034 | AC29: =IF(P29>0,SUM(V29:V40),"-") -> - | AD29: =IF(P29>0,SUM(W29:W40),"-") -> - | AF29: =IF('[29]Proforma-Input'!$C$108="Yes",MONTH(O29)&YEAR(O29)=MONTH($C$9)&YEAR($C$9),0) -> 0 | AG29: 2
B30: =IFERROR(DATE(YEAR(B29),MONTH(B29)+1,DAY(B29)),"-") -> - | D30: 16 | E30: =1+E29 -> 4 | F30: =IFERROR(IF(B30<$C$9,IF('[29]Proforma-Input'!$C$108="Yes",K29,K29),0),) -> 0 | G30: =IFERROR(IF(D30=$C$7,K29,IF(AND($D$10="Yes",D30<=$C$10),I30,IF(F30>0,$C$8,))),) -> 0 | H30: =IFERROR(IF(B30<$C$9,IF('[29]Proforma-Input'!$C$108="Yes",H29,),0),) -> 0 | I30: =(H30/12)*F30 -> 0 | J30: =IF(D30=$C$7,0,G30-I30) -> 0 | K30: =IFERROR(F30-J30,) -> 0 | L30: =IF(C30>0,SUM(I30:I41),"-") -> - | M30: =IF(C30>0,SUM(J30:J41),"-") -> - | O30: =IFERROR(DATE(YEAR(O29),MONTH(O29)+1,DAY(O29)),"-") -> 46390 | Q30: =IF(S30>0,1+Q29,) -> 16 | R30: =1+R29 -> 4 | S30: =IF('[29]Proforma-Input'!$C$108="No",X29,IF(AF30=TRUE,$P$3,X29)) -> 9570905.2 | T30: =IF(AND($N$8="Yes",Q30<=$P$8),V30,IF(S30>0,$P$7,)) -> 63236.743 | U30: =$P$4 -> 0.068 | V30: =IF(S30>0,U30/12*S30,0) -> 54235.13 | W30: =T30-V30 -> 9001.6135 | X30: =S30-W30 -> 9561903.6 | Y30: =IF(Q30=1,V30,Y29+V30) -> 873691.52 | Z30: =IF(Q30=1,W30,Z29+W30) -> 138096.37 | AA30: =$P$9*S30/12 -> 797.57544 | AB30: =$P$10*AA30 -> 199.39386 | AC30: =IF(P30>0,SUM(V30:V41),"-") -> - | AD30: =IF(P30>0,SUM(W30:W41),"-") -> - | AF30: =IF('[29]Proforma-Input'!$C$108="Yes",MONTH(O30)&YEAR(O30)=MONTH($C$9)&YEAR($C$9),0) -> 0 | AG30: 2
B31: =IFERROR(DATE(YEAR(B30),MONTH(B30)+1,DAY(B30)),"-") -> - | D31: 17 | E31: =1+E30 -> 5 | F31: =IFERROR(IF(B31<$C$9,IF('[29]Proforma-Input'!$C$108="Yes",K30,K30),0),) -> 0 | G31: =IFERROR(IF(D31=$C$7,K30,IF(AND($D$10="Yes",D31<=$C$10),I31,IF(F31>0,$C$8,))),) -> 0 | H31: =IFERROR(IF(B31<$C$9,IF('[29]Proforma-Input'!$C$108="Yes",H30,),0),) -> 0 | I31: =(H31/12)*F31 -> 0 | J31: =IF(D31=$C$7,0,G31-I31) -> 0 | K31: =IFERROR(F31-J31,) -> 0 | L31: =IF(C31>0,SUM(I31:I42),"-") -> - | M31: =IF(C31>0,SUM(J31:J42),"-") -> - | O31: =IFERROR(DATE(YEAR(O30),MONTH(O30)+1,DAY(O30)),"-") -> 46421 | Q31: =IF(S31>0,1+Q30,) -> 17 | R31: =1+R30 -> 5 | S31: =IF('[29]Proforma-Input'!$C$108="No",X30,IF(AF31=TRUE,$P$3,X30)) -> 9561903.6 | T31: =IF(AND($N$8="Yes",Q31<=$P$8),V31,IF(S31>0,$P$7,)) -> 63236.743 | U31: =$P$4 -> 0.068 | V31: =IF(S31>0,U31/12*S31,0) -> 54184.121 | W31: =T31-V31 -> 9052.6227 | X31: =S31-W31 -> 9552851 | Y31: =IF(Q31=1,V31,Y30+V31) -> 927875.64 | Z31: =IF(Q31=1,W31,Z30+W31) -> 147148.99 | AA31: =$P$9*S31/12 -> 796.8253 | AB31: =$P$10*AA31 -> 199.20633 | AC31: =IF(P31>0,SUM(V31:V42),"-") -> - | AD31: =IF(P31>0,SUM(W31:W42),"-") -> - | AF31: =IF('[29]Proforma-Input'!$C$108="Yes",MONTH(O31)&YEAR(O31)=MONTH($C$9)&YEAR($C$9),0) -> 0 | AG31: 2
B32: =IFERROR(DATE(YEAR(B31),MONTH(B31)+1,DAY(B31)),"-") -> - | D32: 18 | E32: =1+E31 -> 6 | F32: =IFERROR(IF(B32<$C$9,IF('[29]Proforma-Input'!$C$108="Yes",K31,K31),0),) -> 0 | G32: =IFERROR(IF(D32=$C$7,K31,IF(AND($D$10="Yes",D32<=$C$10),I32,IF(F32>0,$C$8,))),) -> 0 | H32: =IFERROR(IF(B32<$C$9,IF('[29]Proforma-Input'!$C$108="Yes",H31,),0),) -> 0 | I32: =(H32/12)*F32 -> 0 | J32: =IF(D32=$C$7,0,G32-I32) -> 0 | K32: =IFERROR(F32-J32,) -> 0 | L32: =IF(C32>0,SUM(I32:I43),"-") -> - | M32: =IF(C32>0,SUM(J32:J43),"-") -> - | O32: =IFERROR(DATE(YEAR(O31),MONTH(O31)+1,DAY(O31)),"-") -> 46449 | Q32: =IF(S32>0,1+Q31,) -> 18 | R32: =1+R31 -> 6 | S32: =IF('[29]Proforma-Input'!$C$108="No",X31,IF(AF32=TRUE,$P$3,X31)) -> 9552851 | T32: =IF(AND($N$8="Yes",Q32<=$P$8),V32,IF(S32>0,$P$7,)) -> 63236.743 | U32: =$P$4 -> 0.068 | V32: =IF(S32>0,U32/12*S32,0) -> 54132.822 | W32: =T32-V32 -> 9103.9209 | X32: =S32-W32 -> 9543747.1 | Y32: =IF(Q32=1,V32,Y31+V32) -> 982008.47 | Z32: =IF(Q32=1,W32,Z31+W32) -> 156252.91 | AA32: =$P$9*S32/12 -> 796.07092 | AB32: =$P$10*AA32 -> 199.01773 | AC32: =IF(P32>0,SUM(V32:V43),"-") -> - | AD32: =IF(P32>0,SUM(W32:W43),"-") -> - | AF32: =IF('[29]Proforma-Input'!$C$108="Yes",MONTH(O32)&YEAR(O32)=MONTH($C$9)&YEAR($C$9),0) -> 0 | AG32: 2
B33: =IFERROR(DATE(YEAR(B32),MONTH(B32)+1,DAY(B32)),"-") -> - | D33: 19 | E33: =1+E32 -> 7 | F33: =IFERROR(IF(B33<$C$9,IF('[29]Proforma-Input'!$C$108="Yes",K32,K32),0),) -> 0 | G33: =IFERROR(IF(D33=$C$7,K32,IF(AND($D$10="Yes",D33<=$C$10),I33,IF(F33>0,$C$8,))),) -> 0 | H33: =IFERROR(IF(B33<$C$9,IF('[29]Proforma-Input'!$C$108="Yes",H32,),0),) -> 0 | I33: =(H33/12)*F33 -> 0 | J33: =IF(D33=$C$7,0,G33-I33) -> 0 | K33: =IFERROR(F33-J33,) -> 0 | L33: =IF(C33>0,SUM(I33:I44),"-") -> - | M33: =IF(C33>0,SUM(J33:J44),"-") -> - | O33: =IFERROR(DATE(YEAR(O32),MONTH(O32)+1,DAY(O32)),"-") -> 46480 | Q33: =IF(S33>0,1+Q32,) -> 19 | R33: =1+R32 -> 7 | S33: =IF('[29]Proforma-Input'!$C$108="No",X32,IF(AF33=TRUE,$P$3,X32)) -> 9543747.1 | T33: =IF(AND($N$8="Yes",Q33<=$P$8),V33,IF(S33>0,$P$7,)) -> 63236.743 | U33: =$P$4 -> 0.068 | V33: =IF(S33>0,U33/12*S33,0) -> 54081.233 | W33: =T33-V33 -> 9155.5098 | X33: =S33-W33 -> 9534591.6 | Y33: =IF(Q33=1,V33,Y32+V33) -> 1036089.7 | Z33: =IF(Q33=1,W33,Z32+W33) -> 165408.42 | AA33: =$P$9*S33/12 -> 795.31226 | AB33: =$P$10*AA33 -> 198.82806 | AC33: =IF(P33>0,SUM(V33:V44),"-") -> - | AD33: =IF(P33>0,SUM(W33:W44),"-") -> - | AF33: =IF('[29]Proforma-Input'!$C$108="Yes",MONTH(O33)&YEAR(O33)=MONTH($C$9)&YEAR($C$9),0) -> 0 | AG33: 2
B34: =IFERROR(DATE(YEAR(B33),MONTH(B33)+1,DAY(B33)),"-") -> - | D34: 20 | E34: =1+E33 -> 8 | F34: =IFERROR(IF(B34<$C$9,IF('[29]Proforma-Input'!$C$108="Yes",K33,K33),0),) -> 0 | G34: =IFERROR(IF(D34=$C$7,K33,IF(AND($D$10="Yes",D34<=$C$10),I34,IF(F34>0,$C$8,))),) -> 0 | H34: =IFERROR(IF(B34<$C$9,IF('[29]Proforma-Input'!$C$108="Yes",H33,),0),) -> 0 | I34: =(H34/12)*F34 -> 0 | J34: =IF(D34=$C$7,0,G34-I34) -> 0 | K34: =IFERROR(F34-J34,) -> 0 | L34: =IF(C34>0,SUM(I34:I45),"-") -> - | M34: =IF(C34>0,SUM(J34:J45),"-") -> - | O34: =IFERROR(DATE(YEAR(O33),MONTH(O33)+1,DAY(O33)),"-") -> 46510 | Q34: =IF(S34>0,1+Q33,) -> 20 | R34: =1+R33 -> 8 | S34: =IF('[29]Proforma-Input'!$C$108="No",X33,IF(AF34=TRUE,$P$3,X33)) -> 9534591.6 | T34: =IF(AND($N$8="Yes",Q34<=$P$8),V34,IF(S34>0,$P$7,)) -> 63236.743 | U34: =$P$4 -> 0.068 | V34: =IF(S34>0,U34/12*S34,0) -> 54029.352 | W34: =T34-V34 -> 9207.391 | X34: =S34-W34 -> 9525384.2 | Y34: =IF(Q34=1,V34,Y33+V34) -> 1090119.1 | Z34: =IF(Q34=1,W34,Z33+W34) -> 174615.81 | AA34: =$P$9*S34/12 -> 794.5493 | AB34: =$P$10*AA34 -> 198.63732 | AC34: =IF(P34>0,SUM(V34:V45),"-") -> - | AD34: =IF(P34>0,SUM(W34:W45),"-") -> - | AF34: =IF('[29]Proforma-Input'!$C$108="Yes",MONTH(O34)&YEAR(O34)=MONTH($C$9)&YEAR($C$9),0) -> 0 | AG34: 2
B35: =IFERROR(DATE(YEAR(B34),MONTH(B34)+1,DAY(B34)),"-") -> - | D35: 21 | E35: =1+E34 -> 9 | F35: =IFERROR(IF(B35<$C$9,IF('[29]Proforma-Input'!$C$108="Yes",K34,K34),0),) -> 0 | G35: =IFERROR(IF(D35=$C$7,K34,IF(AND($D$10="Yes",D35<=$C$10),I35,IF(F35>0,$C$8,))),) -> 0 | H35: =IFERROR(IF(B35<$C$9,IF('[29]Proforma-Input'!$C$108="Yes",H34,),0),) -> 0 | I35: =(H35/12)*F35 -> 0 | J35: =IF(D35=$C$7,0,G35-I35) -> 0 | K35: =IFERROR(F35-J35,) -> 0 | L35: =IF(C35>0,SUM(I35:I46),"-") -> - | M35: =IF(C35>0,SUM(J35:J46),"-") -> - | O35: =IFERROR(DATE(YEAR(O34),MONTH(O34)+1,DAY(O34)),"-") -> 46541 | Q35: =IF(S35>0,1+Q34,) -> 21 | R35: =1+R34 -> 9 | S35: =IF('[29]Proforma-Input'!$C$108="No",X34,IF(AF35=TRUE,$P$3,X34)) -> 9525384.2 | T35: =IF(AND($N$8="Yes",Q35<=$P$8),V35,IF(S35>0,$P$7,)) -> 63236.743 | U35: =$P$4 -> 0.068 | V35: =IF(S35>0,U35/12*S35,0) -> 53977.177 | W35: =T35-V35 -> 9259.5662 | X35: =S35-W35 -> 9516124.6 | Y35: =IF(Q35=1,V35,Y34+V35) -> 1144096.2 | Z35: =IF(Q35=1,W35,Z34+W35) -> 183875.38 | AA35: =$P$9*S35/12 -> 793.78202 | AB35: =$P$10*AA35 -> 198.4455 | AC35: =IF(P35>0,SUM(V35:V46),"-") -> - | AD35: =IF(P35>0,SUM(W35:W46),"-") -> - | AF35: =IF('[29]Proforma-Input'!$C$108="Yes",MONTH(O35)&YEAR(O35)=MONTH($C$9)&YEAR($C$9),0) -> 0 | AG35: 2
B36: =IFERROR(DATE(YEAR(B35),MONTH(B35)+1,DAY(B35)),"-") -> - | D36: 22 | E36: =1+E35 -> 10 | F36: =IFERROR(IF(B36<$C$9,IF('[29]Proforma-Input'!$C$108="Yes",K35,K35),0),) -> 0 | G36: =IFERROR(IF(D36=$C$7,K35,IF(AND($D$10="Yes",D36<=$C$10),I36,IF(F36>0,$C$8,))),) -> 0 | H36: =IFERROR(IF(B36<$C$9,IF('[29]Proforma-Input'!$C$108="Yes",H35,),0),) -> 0 | I36: =(H36/12)*F36 -> 0 | J36: =IF(D36=$C$7,0,G36-I36) -> 0 | K36: =IFERROR(F36-J36,) -> 0 | L36: =IF(C36>0,SUM(I36:I47),"-") -> - | M36: =IF(C36>0,SUM(J36:J47),"-") -> - | O36: =IFERROR(DATE(YEAR(O35),MONTH(O35)+1,DAY(O35)),"-") -> 46571 | Q36: =IF(S36>0,1+Q35,) -> 22 | R36: =1+R35 -> 10 | S36: =IF('[29]Proforma-Input'!$C$108="No",X35,IF(AF36=TRUE,$P$3,X35)) -> 9516124.6 | T36: =IF(AND($N$8="Yes",Q36<=$P$8),V36,IF(S36>0,$P$7,)) -> 63236.743 | U36: =$P$4 -> 0.068 | V36: =IF(S36>0,U36/12*S36,0) -> 53924.706 | W36: =T36-V36 -> 9312.0371 | X36: =S36-W36 -> 9506812.6 | Y36: =IF(Q36=1,V36,Y35+V36) -> 1198020.9 | Z36: =IF(Q36=1,W36,Z35+W36) -> 193187.42 | AA36: =$P$9*S36/12 -> 793.01039 | AB36: =$P$10*AA36 -> 198.2526 | AC36: =IF(P36>0,SUM(V36:V47),"-") -> - | AD36: =IF(P36>0,SUM(W36:W47),"-") -> - | AF36: =IF('[29]Proforma-Input'!$C$108="Yes",MONTH(O36)&YEAR(O36)=MONTH($C$9)&YEAR($C$9),0) -> 0 | AG36: 2
B37: =IFERROR(DATE(YEAR(B36),MONTH(B36)+1,DAY(B36)),"-") -> - | D37: 23 | E37: =1+E36 -> 11 | F37: =IFERROR(IF(B37<$C$9,IF('[29]Proforma-Input'!$C$108="Yes",K36,K36),0),) -> 0 | G37: =IFERROR(IF(D37=$C$7,K36,IF(AND($D$10="Yes",D37<=$C$10),I37,IF(F37>0,$C$8,))),) -> 0 | H37: =IFERROR(IF(B37<$C$9,IF('[29]Proforma-Input'!$C$108="Yes",H36,),0),) -> 0 | I37: =(H37/12)*F37 -> 0 | J37: =IF(D37=$C$7,0,G37-I37) -> 0 | K37: =IFERROR(F37-J37,) -> 0 | L37: =IF(C37>0,SUM(I37:I48),"-") -> - | M37: =IF(C37>0,SUM(J37:J48),"-") -> - | O37: =IFERROR(DATE(YEAR(O36),MONTH(O36)+1,DAY(O36)),"-") -> 46602 | Q37: =IF(S37>0,1+Q36,) -> 23 | R37: =1+R36 -> 11 | S37: =IF('[29]Proforma-Input'!$C$108="No",X36,IF(AF37=TRUE,$P$3,X36)) -> 9506812.6 | T37: =IF(AND($N$8="Yes",Q37<=$P$8),V37,IF(S37>0,$P$7,)) -> 63236.743 | U37: =$P$4 -> 0.068 | V37: =IF(S37>0,U37/12*S37,0) -> 53871.938 | W37: =T37-V37 -> 9364.8053 | X37: =S37-W37 -> 9497447.8 | Y37: =IF(Q37=1,V37,Y36+V37) -> 1251892.9 | Z37: =IF(Q37=1,W37,Z36+W37) -> 202552.22 | AA37: =$P$9*S37/12 -> 792.23438 | AB37: =$P$10*AA37 -> 198.0586 | AC37: =IF(P37>0,SUM(V37:V48),"-") -> - | AD37: =IF(P37>0,SUM(W37:W48),"-") -> - | AF37: =IF('[29]Proforma-Input'!$C$108="Yes",MONTH(O37)&YEAR(O37)=MONTH($C$9)&YEAR($C$9),0) -> 0 | AG37: 2
B38: =IFERROR(DATE(YEAR(B37),MONTH(B37)+1,DAY(B37)),"-") -> - | D38: 24 | E38: =1+E37 -> 12 | F38: =IFERROR(IF(B38<$C$9,IF('[29]Proforma-Input'!$C$108="Yes",K37,K37),0),) -> 0 | G38: =IFERROR(IF(D38=$C$7,K37,IF(AND($D$10="Yes",D38<=$C$10),I38,IF(F38>0,$C$8,))),) -> 0 | H38: =IFERROR(IF(B38<$C$9,IF('[29]Proforma-Input'!$C$108="Yes",H37,),0),) -> 0 | I38: =(H38/12)*F38 -> 0 | J38: =IF(D38=$C$7,0,G38-I38) -> 0 | K38: =IFERROR(F38-J38,) -> 0 | L38: =IF(C38>0,SUM(I38:I49),"-") -> - | M38: =IF(C38>0,SUM(J38:J49),"-") -> - | O38: =IFERROR(DATE(YEAR(O37),MONTH(O37)+1,DAY(O37)),"-") -> 46633 | Q38: =IF(S38>0,1+Q37,) -> 24 | R38: =1+R37 -> 12 | S38: =IF('[29]Proforma-Input'!$C$108="No",X37,IF(AF38=TRUE,$P$3,X37)) -> 9497447.8 | T38: =IF(AND($N$8="Yes",Q38<=$P$8),V38,IF(S38>0,$P$7,)) -> 63236.743 | U38: =$P$4 -> 0.068 | V38: =IF(S38>0,U38/12*S38,0) -> 53818.871 | W38: =T38-V38 -> 9417.8725 | X38: =S38-W38 -> 9488029.9 | Y38: =IF(Q38=1,V38,Y37+V38) -> 1305711.7 | Z38: =IF(Q38=1,W38,Z37+W38) -> 211970.09 | AA38: =$P$9*S38/12 -> 791.45398 | AB38: =$P$10*AA38 -> 197.8635 | AC38: =IF(P38>0,SUM(V38:V49),"-") -> - | AD38: =IF(P38>0,SUM(W38:W49),"-") -> - | AF38: =IF('[29]Proforma-Input'!$C$108="Yes",MONTH(O38)&YEAR(O38)=MONTH($C$9)&YEAR($C$9),0) -> 0 | AG38: 2
B39: =IFERROR(DATE(YEAR(B38),MONTH(B38)+1,DAY(B38)),"-") -> - | C39: 3 | D39: 25 | E39: 1 | F39: =IFERROR(IF(B39<$C$9,IF('[29]Proforma-Input'!$C$108="Yes",K38,K38),0),) -> 0 | G39: =IFERROR(IF(D39=$C$7,K38,IF(AND($D$10="Yes",D39<=$C$10),I39,IF(F39>0,$C$8,))),) -> 0 | H39: =IFERROR(IF(B39<$C$9,IF('[29]Proforma-Input'!$C$108="Yes",H38,),0),) -> 0 | I39: =(H39/12)*F39 -> 0 | J39: =IF(D39=$C$7,0,G39-I39) -> 0 | K39: =IFERROR(F39-J39,) -> 0 | L39: =IF(C39>0,SUM(I39:I50),"-") -> 0 | M39: =IF(C39>0,SUM(J39:J50),"-") -> 0 | O39: =IFERROR(DATE(YEAR(O38),MONTH(O38)+1,DAY(O38)),"-") -> 46663 | P39: 3 | Q39: =IF(S39>0,1+Q38,) -> 25 | R39: 1 | S39: =IF('[29]Proforma-Input'!$C$108="No",X38,IF(AF39=TRUE,$P$3,X38)) -> 9488029.9 | T39: =IF(AND($N$8="Yes",Q39<=$P$8),V39,IF(S39>0,$P$7,)) -> 63236.743 | U39: =$P$4 -> 0.068 | V39: =IF(S39>0,U39/12*S39,0) -> 53765.503 | W39: =T39-V39 -> 9471.2404 | X39: =S39-W39 -> 9478558.7 | Y39: =IF(Q39=1,V39,Y38+V39) -> 1359477.2 | Z39: =IF(Q39=1,W39,Z38+W39) -> 221441.33 | AA39: =$P$9*S39/12 -> 790.66916 | AB39: =$P$10*AA39 -> 197.66729 | AC39: =IF(P39>0,SUM(V39:V50),"-") -> 641576.02 | AD39: =IF(P39>0,SUM(W39:W50),"-") -> 117264.9 | AF39: =IF('[29]Proforma-Input'!$C$108="Yes",MONTH(O39)&YEAR(O39)=MONTH($C$9)&YEAR($C$9),0) -> 0 | AG39: 3
B40: =IFERROR(DATE(YEAR(B39),MONTH(B39)+1,DAY(B39)),"-") -> - | D40: 26 | E40: =1+E39 -> 2 | F40: =IFERROR(IF(B40<$C$9,IF('[29]Proforma-Input'!$C$108="Yes",K39,K39),0),) -> 0 | G40: =IFERROR(IF(D40=$C$7,K39,IF(AND($D$10="Yes",D40<=$C$10),I40,IF(F40>0,$C$8,))),) -> 0 | H40: =IFERROR(IF(B40<$C$9,IF('[29]Proforma-Input'!$C$108="Yes",H39,),0),) -> 0 | I40: =(H40/12)*F40 -> 0 | J40: =IF(D40=$C$7,0,G40-I40) -> 0 | K40: =IFERROR(F40-J40,) -> 0 | L40: =IF(C40>0,SUM(I40:I51),"-") -> - | M40: =IF(C40>0,SUM(J40:J51),"-") -> - | O40: =IFERROR(DATE(YEAR(O39),MONTH(O39)+1,DAY(O39)),"-") -> 46694 | Q40: =IF(S40>0,1+Q39,) -> 26 | R40: =1+R39 -> 2 | S40: =IF('[29]Proforma-Input'!$C$108="No",X39,IF(AF40=TRUE,$P$3,X39)) -> 9478558.7 | T40: =IF(AND($N$8="Yes",Q40<=$P$8),V40,IF(S40>0,$P$7,)) -> 63236.743 | U40: =$P$4 -> 0.068 | V40: =IF(S40>0,U40/12*S40,0) -> 53711.832 | W40: =T40-V40 -> 9524.9108 | X40: =S40-W40 -> 9469033.8 | Y40: =IF(Q40=1,V40,Y39+V40) -> 1413189.1 | Z40: =IF(Q40=1,W40,Z39+W40) -> 230966.24 | AA40: =$P$9*S40/12 -> 789.87989 | AB40: =$P$10*AA40 -> 197.46997 | AC40: =IF(P40>0,SUM(V40:V51),"-") -> - | AD40: =IF(P40>0,SUM(W40:W51),"-") -> - | AF40: =IF('[29]Proforma-Input'!$C$108="Yes",MONTH(O40)&YEAR(O40)=MONTH($C$9)&YEAR($C$9),0) -> 0 | AG40: 3
B41: =IFERROR(DATE(YEAR(B40),MONTH(B40)+1,DAY(B40)),"-") -> - | D41: 27 | E41: =1+E40 -> 3 | F41: =IFERROR(IF(B41<$C$9,IF('[29]Proforma-Input'!$C$108="Yes",K40,K40),0),) -> 0 | G41: =IFERROR(IF(D41=$C$7,K40,IF(AND($D$10="Yes",D41<=$C$10),I41,IF(F41>0,$C$8,))),) -> 0 | H41: =IFERROR(IF(B41<$C$9,IF('[29]Proforma-Input'!$C$108="Yes",H40,),0),) -> 0 | I41: =(H41/12)*F41 -> 0 | J41: =IF(D41=$C$7,0,G41-I41) -> 0 | K41: =IFERROR(F41-J41,) -> 0 | L41: =IF(C41>0,SUM(I41:I52),"-") -> - | M41: =IF(C41>0,SUM(J41:J52),"-") -> - | O41: =IFERROR(DATE(YEAR(O40),MONTH(O40)+1,DAY(O40)),"-") -> 46724 | Q41: =IF(S41>0,1+Q40,) -> 27 | R41: =1+R40 -> 3 | S41: =IF('[29]Proforma-Input'!$C$108="No",X40,IF(AF41=TRUE,$P$3,X40)) -> 9469033.8 | T41: =IF(AND($N$8="Yes",Q41<=$P$8),V41,IF(S41>0,$P$7,)) -> 63236.743 | U41: =$P$4 -> 0.068 | V41: =IF(S41>0,U41/12*S41,0) -> 53657.858 | W41: =T41-V41 -> 9578.8853 | X41: =S41-W41 -> 9459454.9 | Y41: =IF(Q41=1,V41,Y40+V41) -> 1466846.9 | Z41: =IF(Q41=1,W41,Z40+W41) -> 240545.13 | AA41: =$P$9*S41/12 -> 789.08615 | AB41: =$P$10*AA41 -> 197.27154 | AC41: =IF(P41>0,SUM(V41:V52),"-") -> - | AD41: =IF(P41>0,SUM(W41:W52),"-") -> - | AF41: =IF('[29]Proforma-Input'!$C$108="Yes",MONTH(O41)&YEAR(O41)=MONTH($C$9)&YEAR($C$9),0) -> 0 | AG41: 3
B42: =IFERROR(DATE(YEAR(B41),MONTH(B41)+1,DAY(B41)),"-") -> - | D42: 28 | E42: =1+E41 -> 4 | F42: =IFERROR(IF(B42<$C$9,IF('[29]Proforma-Input'!$C$108="Yes",K41,K41),0),) -> 0 | G42: =IFERROR(IF(D42=$C$7,K41,IF(AND($D$10="Yes",D42<=$C$10),I42,IF(F42>0,$C$8,))),) -> 0 | H42: =IFERROR(IF(B42<$C$9,IF('[29]Proforma-Input'!$C$108="Yes",H41,),0),) -> 0 | I42: =(H42/12)*F42 -> 0 | J42: =IF(D42=$C$7,0,G42-I42) -> 0 | K42: =IFERROR(F42-J42,) -> 0 | L42: =IF(C42>0,SUM(I42:I53),"-") -> - | M42: =IF(C42>0,SUM(J42:J53),"-") -> - | O42: =IFERROR(DATE(YEAR(O41),MONTH(O41)+1,DAY(O41)),"-") -> 46755 | Q42: =IF(S42>0,1+Q41,) -> 28 | R42: =1+R41 -> 4 | S42: =IF('[29]Proforma-Input'!$C$108="No",X41,IF(AF42=TRUE,$P$3,X41)) -> 9459454.9 | T42: =IF(AND($N$8="Yes",Q42<=$P$8),V42,IF(S42>0,$P$7,)) -> 63236.743 | U42: =$P$4 -> 0.068 | V42: =IF(S42>0,U42/12*S42,0) -> 53603.578 | W42: =T42-V42 -> 9633.1657 | X42: =S42-W42 -> 9449821.7 | Y42: =IF(Q42=1,V42,Y41+V42) -> 1520450.5 | Z42: =IF(Q42=1,W42,Z41+W42) -> 250178.3 | AA42: =$P$9*S42/12 -> 788.28791 | AB42: =$P$10*AA42 -> 197.07198 | AC42: =IF(P42>0,SUM(V42:V53),"-") -> - | AD42: =IF(P42>0,SUM(W42:W53),"-") -> - | AF42: =IF('[29]Proforma-Input'!$C$108="Yes",MONTH(O42)&YEAR(O42)=MONTH($C$9)&YEAR($C$9),0) -> 0 | AG42: 3
B43: =IFERROR(DATE(YEAR(B42),MONTH(B42)+1,DAY(B42)),"-") -> - | D43: 29 | E43: =1+E42 -> 5 | F43: =IFERROR(IF(B43<$C$9,IF('[29]Proforma-Input'!$C$108="Yes",K42,K42),0),) -> 0 | G43: =IFERROR(IF(D43=$C$7,K42,IF(AND($D$10="Yes",D43<=$C$10),I43,IF(F43>0,$C$8,))),) -> 0 | H43: =IFERROR(IF(B43<$C$9,IF('[29]Proforma-Input'!$C$108="Yes",H42,),0),) -> 0 | I43: =(H43/12)*F43 -> 0 | J43: =IF(D43=$C$7,0,G43-I43) -> 0 | K43: =IFERROR(F43-J43,) -> 0 | L43: =IF(C43>0,SUM(I43:I54),"-") -> - | M43: =IF(C43>0,SUM(J43:J54),"-") -> - | O43: =IFERROR(DATE(YEAR(O42),MONTH(O42)+1,DAY(O42)),"-") -> 46786 | Q43: =IF(S43>0,1+Q42,) -> 29 | R43: =1+R42 -> 5 | S43: =IF('[29]Proforma-Input'!$C$108="No",X42,IF(AF43=TRUE,$P$3,X42)) -> 9449821.7 | T43: =IF(AND($N$8="Yes",Q43<=$P$8),V43,IF(S43>0,$P$7,)) -> 63236.743 | U43: =$P$4 -> 0.068 | V43: =IF(S43>0,U43/12*S43,0) -> 53548.99 | W43: =T43-V43 -> 9687.7536 | X43: =S43-W43 -> 9440134 | Y43: =IF(Q43=1,V43,Y42+V43) -> 1573999.5 | Z43: =IF(Q43=1,W43,Z42+W43) -> 259866.05 | AA43: =$P$9*S43/12 -> 787.48514 | AB43: =$P$10*AA43 -> 196.87129 | AC43: =IF(P43>0,SUM(V43:V54),"-") -> - | AD43: =IF(P43>0,SUM(W43:W54),"-") -> - | AF43: =IF('[29]Proforma-Input'!$C$108="Yes",MONTH(O43)&YEAR(O43)=MONTH($C$9)&YEAR($C$9),0) -> 0 | AG43: 3
...

Sheet 0-5M
B2: Assumable Loan Info | O2: New Loan Info | T2: Annual Service Fee | U2: Matthews Split | V2: 10 Loans
B3: Original Loan Balance | C3: ='[29]Proforma-Input'!E113 -> #REF! | O3: New Loan Balance | P3: 5000000 | S3: Year 1 | T3: =SUM(AA16:AA27) -> 4974.6852 | U3: =SUM(AB16:AB27) -> 497.46852 | V3: =U3*10 -> 4974.6852
B4: Existing Loan Balance | C4: ='[29]Proforma-Input'!E114 -> 0 | O4: Interest Rate | P4: 0.065 | S4: Year 2 | T4: =SUM(AA28:AA39) -> 4917.1036 | U4: =SUM(AB28:AB39) -> 491.71036 | V4: =U4*10 -> 4917.1036
B5: Interest Rate | C5: ='[29]Proforma-Input'!K113 -> #REF! | O5: Amortization (In Years) | P5: 30 | S5: Year 3 | T5: =SUM(AA40:AA51) -> 4855.6656 | U5: =SUM(AB40:AB51) -> 485.56656 | V5: =U5*10 -> 4855.6656
B6: Amortization (In Years) | C6: ='[29]Proforma-Input'!K110 -> #REF! | O6: Term(Years) | P6: 5 | S6: Year 4 | T6: =SUM(AA52:AA63) -> 4790.113 | U6: =SUM(AB52:AB63) -> 479.0113 | V6: =U6*10 -> 4790.113
B7: Remaining Term in Months | C7: ='[29]Optimistic Return Calculation'!E54 -> 0 | O7: Monthly Payment | P7: =PMT(P4/12,P5*12,-P3,0) -> 31603.401 | S7: Year 5 | T7: =SUM(AA64:AA75) -> 4720.1702 | U7: =SUM(AB64:AB75) -> 472.01702 | V7: =U7*10 -> 4720.1702
B8: Monthly Payment | C8: ='[29]Proforma-Input'!K114 -> 0 | N8: Yes | O8: I/O(Monthly): | P8: 0 | Q8: Total(Term)
B9: Final Payment Date | C9: =IFERROR('[29]Proforma-Input'!E111+(C7*30),"-") -> - | O9: Service Fee | P9: 0.001 | Q9: =SUMIFS($AA$16:$AA$375, $Q$16:$Q$375, "<=" & 12 * $P$6) -> 24257.738
B10: IO: | C10: =IFERROR('[29]Proforma-Input'!K116*12,"-") -> - | D10: =IF(C10>0,"Yes","No") -> Yes | O10: Matthews Split | P10: 0.1 | Q10: =SUMIFS($AB$16:$AB$375, $Q$16:$Q$375, "<=" & 12 * $P$6) -> 2425.7738
C14: Assumable Loan Table | P14: Loan Calculations
B15: Month | C15: Year | D15: # of Months | E15: Month/Year | F15: Beg. Balance | G15: Payment | H15: Rate | I15: Interest | J15: Principal | K15: End Balance | L15: Interest/Year | M15: Principal/Year | O15: Month | P15: Year | Q15: # of Months | R15: Month/Year | S15: Beg. Balance | T15: Payment | U15: Rate | V15: Interest | W15: Principal | X15: End Balance | Y15: Cumulative Interest | Z15: Cumulative Principal | AA15: Service Fee | AB15: Matthews Split | AC15: Interest/Year | AD15: Principal/Year | AF15: Input Data
B16: ='[29]Proforma-Input'!$E$111 -> - | C16: 1 | D16: 1 | E16: 1 | F16: =IF('[29]Proforma-Input'!$C$108="Yes",$C$4,) -> 0 | G16: =IF(AND($D$10="Yes",D16<=$C$10),I16,IF(F16>0,$C$8,)) -> 0 | H16: =IF('[29]Proforma-Input'!$C$108="Yes",C5,) -> 0 | I16: =(H16/12)*F16 -> 0 | J16: =IF(D16=$C$7,0,G16-I16) -> 0 | K16: =IFERROR(F16-J16,) -> 0 | L16: =IF(C16>0,SUM(I16:I27),"-") -> 0 | M16: =IF(C16>0,SUM(J16:J27),"-") -> 0 | O16: =NOW() -> 45933.485 | P16: 1 | Q16: =IF(S16>0,1,) -> 1 | R16: 1 | S16: =IF('[29]Proforma-Input'!$C$108="No",$P$3,IF(AF16="True",$P$3,)) -> 5000000 | T16: =IF(AND($N$8="Yes",Q16<=$P$8),V16,IF(S16>0,$P$7,)) -> 31603.401 | U16: =$P$4 -> 0.065 | V16: =IF(S16>0,U16/12*S16,0) -> 27083.333 | W16: =T16-V16 -> 4520.0678 | X16: =S16-W16 -> 4995479.9 | Y16: =IF(Q16=1,V16,Y15+V16) -> 27083.333 | Z16: =IF(Q16=1,W16,Z15+W16) -> 4520.0678 | AA16: =$P$9*S16/12 -> 416.66667 | AB16: =$P$10*AA16 -> 41.666667 | AC16: =IF(P16>0,SUM(V16:V27),"-") -> 323354.54 | AD16: =IF(P16>0,SUM(W16:W27),"-") -> 55886.273 | AF16: =IF('[29]Proforma-Input'!$C$108="Yes",MONTH(O16)&YEAR(O16)=MONTH($C$9)&YEAR($C$9),0) -> 0 | AG16: 1
B17: =IFERROR(DATE(YEAR(B16),MONTH(B16)+1,DAY(B16)),"-") -> - | D17: 2 | E17: =1+E16 -> 2 | F17: =IFERROR(IF(B17<$C$9,IF('[29]Proforma-Input'!$C$108="Yes",K16,K16),0),) -> 0 | G17: =IFERROR(IF(D17=$C$7,K16,IF(AND($D$10="Yes",D17<=$C$10),I17,IF(F17>0,$C$8,))),) -> 0 | H17: =IFERROR(IF(B17<$C$9,IF('[29]Proforma-Input'!$C$108="Yes",H16,),0),) -> 0 | I17: =(H17/12)*F17 -> 0 | J17: =IF(D17=$C$7,0,G17-I17) -> 0 | K17: =IFERROR(F17-J17,) -> 0 | L17: =IF(C17>0,SUM(I17:I28),"-") -> - | M17: =IF(C17>0,SUM(J17:J28),"-") -> - | O17: =IFERROR(DATE(YEAR(O16),MONTH(O16)+1,DAY(O16)),"-") -> 45964 | Q17: =IF(S17>0,1+Q16,) -> 2 | R17: =1+R16 -> 2 | S17: =IF('[29]Proforma-Input'!$C$108="No",X16,IF(AF17=TRUE,$P$3,X16)) -> 4995479.9 | T17: =IF(AND($N$8="Yes",Q17<=$P$8),V17,IF(S17>0,$P$7,)) -> 31603.401 | U17: =$P$4 -> 0.065 | V17: =IF(S17>0,U17/12*S17,0) -> 27058.85 | W17: =T17-V17 -> 4544.5515 | X17: =S17-W17 -> 4990935.4 | Y17: =IF(Q17=1,V17,Y16+V17) -> 54142.183 | Z17: =IF(Q17=1,W17,Z16+W17) -> 9064.6194 | AA17: =$P$9*S17/12 -> 416.28999 | AB17: =$P$10*AA17 -> 41.628999 | AC17: =IF(P17>0,SUM(V17:V28),"-") -> - | AD17: =IF(P17>0,SUM(W17:W28),"-") -> - | AF17: =IF('[29]Proforma-Input'!$C$108="Yes",MONTH(O17)&YEAR(O17)=MONTH($C$9)&YEAR($C$9),0) -> 0 | AG17: 1
B18: =IFERROR(DATE(YEAR(B17),MONTH(B17)+1,DAY(B17)),"-") -> - | D18: 3 | E18: =1+E17 -> 3 | F18: =IFERROR(IF(B18<$C$9,IF('[29]Proforma-Input'!$C$108="Yes",K17,K17),0),) -> 0 | G18: =IFERROR(IF(D18=$C$7,K17,IF(AND($D$10="Yes",D18<=$C$10),I18,IF(F18>0,$C$8,))),) -> 0 | H18: =IFERROR(IF(B18<$C$9,IF('[29]Proforma-Input'!$C$108="Yes",H17,),0),) -> 0 | I18: =(H18/12)*F18 -> 0 | J18: =IF(D18=$C$7,0,G18-I18) -> 0 | K18: =IFERROR(F18-J18,) -> 0 | L18: =IF(C18>0,SUM(I18:I29),"-") -> - | M18: =IF(C18>0,SUM(J18:J29),"-") -> - | O18: =IFERROR(DATE(YEAR(O17),MONTH(O17)+1,DAY(O17)),"-") -> 45994 | Q18: =IF(S18>0,1+Q17,) -> 3 | R18: =1+R17 -> 3 | S18: =IF('[29]Proforma-Input'!$C$108="No",X17,IF(AF18=TRUE,$P$3,X17)) -> 4990935.4 | T18: =IF(AND($N$8="Yes",Q18<=$P$8),V18,IF(S18>0,$P$7,)) -> 31603.401 | U18: =$P$4 -> 0.065 | V18: =IF(S18>0,U18/12*S18,0) -> 27034.233 | W18: =T18-V18 -> 4569.1679 | X18: =S18-W18 -> 4986366.2 | Y18: =IF(Q18=1,V18,Y17+V18) -> 81176.416 | Z18: =IF(Q18=1,W18,Z17+W18) -> 13633.787 | AA18: =$P$9*S18/12 -> 415.91128 | AB18: =$P$10*AA18 -> 41.591128 | AC18: =IF(P18>0,SUM(V18:V29),"-") -> - | AD18: =IF(P18>0,SUM(W18:W29),"-") -> - | AF18: =IF('[29]Proforma-Input'!$C$108="Yes",MONTH(O18)&YEAR(O18)=MONTH($C$9)&YEAR($C$9),0) -> 0 | AG18: 1
B19: =IFERROR(DATE(YEAR(B18),MONTH(B18)+1,DAY(B18)),"-") -> - | D19: 4 | E19: =1+E18 -> 4 | F19: =IFERROR(IF(B19<$C$9,IF('[29]Proforma-Input'!$C$108="Yes",K18,K18),0),) -> 0 | G19: =IFERROR(IF(D19=$C$7,K18,IF(AND($D$10="Yes",D19<=$C$10),I19,IF(F19>0,$C$8,))),) -> 0 | H19: =IFERROR(IF(B19<$C$9,IF('[29]Proforma-Input'!$C$108="Yes",H18,),0),) -> 0 | I19: =(H19/12)*F19 -> 0 | J19: =IF(D19=$C$7,0,G19-I19) -> 0 | K19: =IFERROR(F19-J19,) -> 0 | L19: =IF(C19>0,SUM(I19:I30),"-") -> - | M19: =IF(C19>0,SUM(J19:J30),"-") -> - | O19: =IFERROR(DATE(YEAR(O18),MONTH(O18)+1,DAY(O18)),"-") -> 46025 | Q19: =IF(S19>0,1+Q18,) -> 4 | R19: =1+R18 -> 4 | S19: =IF('[29]Proforma-Input'!$C$108="No",X18,IF(AF19=TRUE,$P$3,X18)) -> 4986366.2 | T19: =IF(AND($N$8="Yes",Q19<=$P$8),V19,IF(S19>0,$P$7,)) -> 31603.401 | U19: =$P$4 -> 0.065 | V19: =IF(S19>0,U19/12*S19,0) -> 27009.484 | W19: =T19-V19 -> 4593.9175 | X19: =S19-W19 -> 4981772.3 | Y19: =IF(Q19=1,V19,Y18+V19) -> 108185.9 | Z19: =IF(Q19=1,W19,Z18+W19) -> 18227.705 | AA19: =$P$9*S19/12 -> 415.53052 | AB19: =$P$10*AA19 -> 41.553052 | AC19: =IF(P19>0,SUM(V19:V30),"-") -> - | AD19: =IF(P19>0,SUM(W19:W30),"-") -> - | AF19: =IF('[29]Proforma-Input'!$C$108="Yes",MONTH(O19)&YEAR(O19)=MONTH($C$9)&YEAR($C$9),0) -> 0 | AG19: 1
B20: =IFERROR(DATE(YEAR(B19),MONTH(B19)+1,DAY(B19)),"-") -> - | D20: 5 | E20: =1+E19 -> 5 | F20: =IFERROR(IF(B20<$C$9,IF('[29]Proforma-Input'!$C$108="Yes",K19,K19),0),) -> 0 | G20: =IFERROR(IF(D20=$C$7,K19,IF(AND($D$10="Yes",D20<=$C$10),I20,IF(F20>0,$C$8,))),) -> 0 | H20: =IFERROR(IF(B20<$C$9,IF('[29]Proforma-Input'!$C$108="Yes",H19,),0),) -> 0 | I20: =(H20/12)*F20 -> 0 | J20: =IF(D20=$C$7,0,G20-I20) -> 0 | K20: =IFERROR(F20-J20,) -> 0 | L20: =IF(C20>0,SUM(I20:I31),"-") -> - | M20: =IF(C20>0,SUM(J20:J31),"-") -> - | O20: =IFERROR(DATE(YEAR(O19),MONTH(O19)+1,DAY(O19)),"-") -> 46056 | Q20: =IF(S20>0,1+Q19,) -> 5 | R20: =1+R19 -> 5 | S20: =IF('[29]Proforma-Input'!$C$108="No",X19,IF(AF20=TRUE,$P$3,X19)) -> 4981772.3 | T20: =IF(AND($N$8="Yes",Q20<=$P$8),V20,IF(S20>0,$P$7,)) -> 31603.401 | U20: =$P$4 -> 0.065 | V20: =IF(S20>0,U20/12*S20,0) -> 26984.6 | W20: =T20-V20 -> 4618.8012 | X20: =S20-W20 -> 4977153.5 | Y20: =IF(Q20=1,V20,Y19+V20) -> 135170.5 | Z20: =IF(Q20=1,W20,Z19+W20) -> 22846.506 | AA20: =$P$9*S20/12 -> 415.14769 | AB20: =$P$10*AA20 -> 41.514769 | AC20: =IF(P20>0,SUM(V20:V31),"-") -> - | AD20: =IF(P20>0,SUM(W20:W31),"-") -> - | AF20: =IF('[29]Proforma-Input'!$C$108="Yes",MONTH(O20)&YEAR(O20)=MONTH($C$9)&YEAR($C$9),0) -> 0 | AG20: 1
B21: =IFERROR(DATE(YEAR(B20),MONTH(B20)+1,DAY(B20)),"-") -> - | D21: 6 | E21: =1+E20 -> 6 | F21: =IFERROR(IF(B21<$C$9,IF('[29]Proforma-Input'!$C$108="Yes",K20,K20),0),) -> 0 | G21: =IFERROR(IF(D21=$C$7,K20,IF(AND($D$10="Yes",D21<=$C$10),I21,IF(F21>0,$C$8,))),) -> 0 | H21: =IFERROR(IF(B21<$C$9,IF('[29]Proforma-Input'!$C$108="Yes",H20,),0),) -> 0 | I21: =(H21/12)*F21 -> 0 | J21: =IF(D21=$C$7,0,G21-I21) -> 0 | K21: =IFERROR(F21-J21,) -> 0 | L21: =IF(C21>0,SUM(I21:I32),"-") -> - | M21: =IF(C21>0,SUM(J21:J32),"-") -> - | O21: =IFERROR(DATE(YEAR(O20),MONTH(O20)+1,DAY(O20)),"-") -> 46084 | Q21: =IF(S21>0,1+Q20,) -> 6 | R21: =1+R20 -> 6 | S21: =IF('[29]Proforma-Input'!$C$108="No",X20,IF(AF21=TRUE,$P$3,X20)) -> 4977153.5 | T21: =IF(AND($N$8="Yes",Q21<=$P$8),V21,IF(S21>0,$P$7,)) -> 31603.401 | U21: =$P$4 -> 0.065 | V21: =IF(S21>0,U21/12*S21,0) -> 26959.581 | W21: =T21-V21 -> 4643.8197 | X21: =S21-W21 -> 4972509.7 | Y21: =IF(Q21=1,V21,Y20+V21) -> 162130.08 | Z21: =IF(Q21=1,W21,Z20+W21) -> 27490.326 | AA21: =$P$9*S21/12 -> 414.76279 | AB21: =$P$10*AA21 -> 41.476279 | AC21: =IF(P21>0,SUM(V21:V32),"-") -> - | AD21: =IF(P21>0,SUM(W21:W32),"-") -> - | AF21: =IF('[29]Proforma-Input'!$C$108="Yes",MONTH(O21)&YEAR(O21)=MONTH($C$9)&YEAR($C$9),0) -> 0 | AG21: 1
B22: =IFERROR(DATE(YEAR(B21),MONTH(B21)+1,DAY(B21)),"-") -> - | D22: 7 | E22: =1+E21 -> 7 | F22: =IFERROR(IF(B22<$C$9,IF('[29]Proforma-Input'!$C$108="Yes",K21,K21),0),) -> 0 | G22: =IFERROR(IF(D22=$C$7,K21,IF(AND($D$10="Yes",D22<=$C$10),I22,IF(F22>0,$C$8,))),) -> 0 | H22: =IFERROR(IF(B22<$C$9,IF('[29]Proforma-Input'!$C$108="Yes",H21,),0),) -> 0 | I22: =(H22/12)*F22 -> 0 | J22: =IF(D22=$C$7,0,G22-I22) -> 0 | K22: =IFERROR(F22-J22,) -> 0 | L22: =IF(C22>0,SUM(I22:I33),"-") -> - | M22: =IF(C22>0,SUM(J22:J33),"-") -> - | O22: =IFERROR(DATE(YEAR(O21),MONTH(O21)+1,DAY(O21)),"-") -> 46115 | Q22: =IF(S22>0,1+Q21,) -> 7 | R22: =1+R21 -> 7 | S22: =IF('[29]Proforma-Input'!$C$108="No",X21,IF(AF22=TRUE,$P$3,X21)) -> 4972509.7 | T22: =IF(AND($N$8="Yes",Q22<=$P$8),V22,IF(S22>0,$P$7,)) -> 31603.401 | U22: =$P$4 -> 0.065 | V22: =IF(S22>0,U22/12*S22,0) -> 26934.427 | W22: =T22-V22 -> 4668.9738 | X22: =S22-W22 -> 4967840.7 | Y22: =IF(Q22=1,V22,Y21+V22) -> 189064.51 | Z22: =IF(Q22=1,W22,Z21+W22) -> 32159.3 | AA22: =$P$9*S22/12 -> 414.37581 | AB22: =$P$10*AA22 -> 41.437581 | AC22: =IF(P22>0,SUM(V22:V33),"-") -> - | AD22: =IF(P22>0,SUM(W22:W33),"-") -> - | AF22: =IF('[29]Proforma-Input'!$C$108="Yes",MONTH(O22)&YEAR(O22)=MONTH($C$9)&YEAR($C$9),0) -> 0 | AG22: 1
B23: =IFERROR(DATE(YEAR(B22),MONTH(B22)+1,DAY(B22)),"-") -> - | D23: 8 | E23: =1+E22 -> 8 | F23: =IFERROR(IF(B23<$C$9,IF('[29]Proforma-Input'!$C$108="Yes",K22,K22),0),) -> 0 | G23: =IFERROR(IF(D23=$C$7,K22,IF(AND($D$10="Yes",D23<=$C$10),I23,IF(F23>0,$C$8,))),) -> 0 | H23: =IFERROR(IF(B23<$C$9,IF('[29]Proforma-Input'!$C$108="Yes",H22,),0),) -> 0 | I23: =(H23/12)*F23 -> 0 | J23: =IF(D23=$C$7,0,G23-I23) -> 0 | K23: =IFERROR(F23-J23,) -> 0 | L23: =IF(C23>0,SUM(I23:I34),"-") -> - | M23: =IF(C23>0,SUM(J23:J34),"-") -> - | O23: =IFERROR(DATE(YEAR(O22),MONTH(O22)+1,DAY(O22)),"-") -> 46145 | Q23: =IF(S23>0,1+Q22,) -> 8 | R23: =1+R22 -> 8 | S23: =IF('[29]Proforma-Input'!$C$108="No",X22,IF(AF23=TRUE,$P$3,X22)) -> 4967840.7 | T23: =IF(AND($N$8="Yes",Q23<=$P$8),V23,IF(S23>0,$P$7,)) -> 31603.401 | U23: =$P$4 -> 0.065 | V23: =IF(S23>0,U23/12*S23,0) -> 26909.137 | W23: =T23-V23 -> 4694.264 | X23: =S23-W23 -> 4963146.4 | Y23: =IF(Q23=1,V23,Y22+V23) -> 215973.65 | Z23: =IF(Q23=1,W23,Z22+W23) -> 36853.564 | AA23: =$P$9*S23/12 -> 413.98673 | AB23: =$P$10*AA23 -> 41.398673 | AC23: =IF(P23>0,SUM(V23:V34),"-") -> - | AD23: =IF(P23>0,SUM(W23:W34),"-") -> - | AF23: =IF('[29]Proforma-Input'!$C$108="Yes",MONTH(O23)&YEAR(O23)=MONTH($C$9)&YEAR($C$9),0) -> 0 | AG23: 1
B24: =IFERROR(DATE(YEAR(B23),MONTH(B23)+1,DAY(B23)),"-") -> - | D24: 9 | E24: =1+E23 -> 9 | F24: =IFERROR(IF(B24<$C$9,IF('[29]Proforma-Input'!$C$108="Yes",K23,K23),0),) -> 0 | G24: =IFERROR(IF(D24=$C$7,K23,IF(AND($D$10="Yes",D24<=$C$10),I24,IF(F24>0,$C$8,))),) -> 0 | H24: =IFERROR(IF(B24<$C$9,IF('[29]Proforma-Input'!$C$108="Yes",H23,),0),) -> 0 | I24: =(H24/12)*F24 -> 0 | J24: =IF(D24=$C$7,0,G24-I24) -> 0 | K24: =IFERROR(F24-J24,) -> 0 | L24: =IF(C24>0,SUM(I24:I35),"-") -> - | M24: =IF(C24>0,SUM(J24:J35),"-") -> - | O24: =IFERROR(DATE(YEAR(O23),MONTH(O23)+1,DAY(O23)),"-") -> 46176 | Q24: =IF(S24>0,1+Q23,) -> 9 | R24: =1+R23 -> 9 | S24: =IF('[29]Proforma-Input'!$C$108="No",X23,IF(AF24=TRUE,$P$3,X23)) -> 4963146.4 | T24: =IF(AND($N$8="Yes",Q24<=$P$8),V24,IF(S24>0,$P$7,)) -> 31603.401 | U24: =$P$4 -> 0.065 | V24: =IF(S24>0,U24/12*S24,0) -> 26883.71 | W24: =T24-V24 -> 4719.6913 | X24: =S24-W24 -> 4958426.7 | Y24: =IF(Q24=1,V24,Y23+V24) -> 242857.36 | Z24: =IF(Q24=1,W24,Z23+W24) -> 41573.255 | AA24: =$P$9*S24/12 -> 413.59554 | AB24: =$P$10*AA24 -> 41.359554 | AC24: =IF(P24>0,SUM(V24:V35),"-") -> - | AD24: =IF(P24>0,SUM(W24:W35),"-") -> - | AF24: =IF('[29]Proforma-Input'!$C$108="Yes",MONTH(O24)&YEAR(O24)=MONTH($C$9)&YEAR($C$9),0) -> 0 | AG24: 1
B25: =IFERROR(DATE(YEAR(B24),MONTH(B24)+1,DAY(B24)),"-") -> - | D25: 10 | E25: =1+E24 -> 10 | F25: =IFERROR(IF(B25<$C$9,IF('[29]Proforma-Input'!$C$108="Yes",K24,K24),0),) -> 0 | G25: =IFERROR(IF(D25=$C$7,K24,IF(AND($D$10="Yes",D25<=$C$10),I25,IF(F25>0,$C$8,))),) -> 0 | H25: =IFERROR(IF(B25<$C$9,IF('[29]Proforma-Input'!$C$108="Yes",H24,),0),) -> 0 | I25: =(H25/12)*F25 -> 0 | J25: =IF(D25=$C$7,0,G25-I25) -> 0 | K25: =IFERROR(F25-J25,) -> 0 | L25: =IF(C25>0,SUM(I25:I36),"-") -> - | M25: =IF(C25>0,SUM(J25:J36),"-") -> - | O25: =IFERROR(DATE(YEAR(O24),MONTH(O24)+1,DAY(O24)),"-") -> 46206 | Q25: =IF(S25>0,1+Q24,) -> 10 | R25: =1+R24 -> 10 | S25: =IF('[29]Proforma-Input'!$C$108="No",X24,IF(AF25=TRUE,$P$3,X24)) -> 4958426.7 | T25: =IF(AND($N$8="Yes",Q25<=$P$8),V25,IF(S25>0,$P$7,)) -> 31603.401 | U25: =$P$4 -> 0.065 | V25: =IF(S25>0,U25/12*S25,0) -> 26858.145 | W25: =T25-V25 -> 4745.2563 | X25: =S25-W25 -> 4953681.5 | Y25: =IF(Q25=1,V25,Y24+V25) -> 269715.5 | Z25: =IF(Q25=1,W25,Z24+W25) -> 46318.511 | AA25: =$P$9*S25/12 -> 413.20223 | AB25: =$P$10*AA25 -> 41.320223 | AC25: =IF(P25>0,SUM(V25:V36),"-") -> - | AD25: =IF(P25>0,SUM(W25:W36),"-") -> - | AF25: =IF('[29]Proforma-Input'!$C$108="Yes",MONTH(O25)&YEAR(O25)=MONTH($C$9)&YEAR($C$9),0) -> 0 | AG25: 1
B26: =IFERROR(DATE(YEAR(B25),MONTH(B25)+1,DAY(B25)),"-") -> - | D26: 11 | E26: =1+E25 -> 11 | F26: =IFERROR(IF(B26<$C$9,IF('[29]Proforma-Input'!$C$108="Yes",K25,K25),0),) -> 0 | G26: =IFERROR(IF(D26=$C$7,K25,IF(AND($D$10="Yes",D26<=$C$10),I26,IF(F26>0,$C$8,))),) -> 0 | H26: =IFERROR(IF(B26<$C$9,IF('[29]Proforma-Input'!$C$108="Yes",H25,),0),) -> 0 | I26: =(H26/12)*F26 -> 0 | J26: =IF(D26=$C$7,0,G26-I26) -> 0 | K26: =IFERROR(F26-J26,) -> 0 | L26: =IF(C26>0,SUM(I26:I37),"-") -> - | M26: =IF(C26>0,SUM(J26:J37),"-") -> - | O26: =IFERROR(DATE(YEAR(O25),MONTH(O25)+1,DAY(O25)),"-") -> 46237 | Q26: =IF(S26>0,1+Q25,) -> 11 | R26: =1+R25 -> 11 | S26: =IF('[29]Proforma-Input'!$C$108="No",X25,IF(AF26=TRUE,$P$3,X25)) -> 4953681.5 | T26: =IF(AND($N$8="Yes",Q26<=$P$8),V26,IF(S26>0,$P$7,)) -> 31603.401 | U26: =$P$4 -> 0.065 | V26: =IF(S26>0,U26/12*S26,0) -> 26832.441 | W26: =T26-V26 -> 4770.9598 | X26: =S26-W26 -> 4948910.5 | Y26: =IF(Q26=1,V26,Y25+V26) -> 296547.94 | Z26: =IF(Q26=1,W26,Z25+W26) -> 51089.471 | AA26: =$P$9*S26/12 -> 412.80679 | AB26: =$P$10*AA26 -> 41.280679 | AC26: =IF(P26>0,SUM(V26:V37),"-") -> - | AD26: =IF(P26>0,SUM(W26:W37),"-") -> - | AF26: =IF('[29]Proforma-Input'!$C$108="Yes",MONTH(O26)&YEAR(O26)=MONTH($C$9)&YEAR($C$9),0) -> 0 | AG26: 1
B27: =IFERROR(DATE(YEAR(B26),MONTH(B26)+1,DAY(B26)),"-") -> - | D27: 12 | E27: =1+E26 -> 12 | F27: =IFERROR(IF(B27<$C$9,IF('[29]Proforma-Input'!$C$108="Yes",K26,K26),0),) -> 0 | G27: =IFERROR(IF(D27=$C$7,K26,IF(AND($D$10="Yes",D27<=$C$10),I27,IF(F27>0,$C$8,))),) -> 0 | H27: =IFERROR(IF(B27<$C$9,IF('[29]Proforma-Input'!$C$108="Yes",H26,),0),) -> 0 | I27: =(H27/12)*F27 -> 0 | J27: =IF(D27=$C$7,0,G27-I27) -> 0 | K27: =IFERROR(F27-J27,) -> 0 | L27: =IF(C27>0,SUM(I27:I38),"-") -> - | M27: =IF(C27>0,SUM(J27:J38),"-") -> - | O27: =IFERROR(DATE(YEAR(O26),MONTH(O26)+1,DAY(O26)),"-") -> 46268 | Q27: =IF(S27>0,1+Q26,) -> 12 | R27: =1+R26 -> 12 | S27: =IF('[29]Proforma-Input'!$C$108="No",X26,IF(AF27=TRUE,$P$3,X26)) -> 4948910.5 | T27: =IF(AND($N$8="Yes",Q27<=$P$8),V27,IF(S27>0,$P$7,)) -> 31603.401 | U27: =$P$4 -> 0.065 | V27: =IF(S27>0,U27/12*S27,0) -> 26806.599 | W27: =T27-V27 -> 4796.8025 | X27: =S27-W27 -> 4944113.7 | Y27: =IF(Q27=1,V27,Y26+V27) -> 323354.54 | Z27: =IF(Q27=1,W27,Z26+W27) -> 55886.273 | AA27: =$P$9*S27/12 -> 412.40921 | AB27: =$P$10*AA27 -> 41.240921 | AC27: =IF(P27>0,SUM(V27:V38),"-") -> - | AD27: =IF(P27>0,SUM(W27:W38),"-") -> - | AF27: =IF('[29]Proforma-Input'!$C$108="Yes",MONTH(O27)&YEAR(O27)=MONTH($C$9)&YEAR($C$9),0) -> 0 | AG27: 1
B28: =IFERROR(DATE(YEAR(B27),MONTH(B27)+1,DAY(B27)),"-") -> - | C28: 2 | D28: 13 | E28: 1 | F28: =IFERROR(IF(B28<$C$9,IF('[29]Proforma-Input'!$C$108="Yes",K27,K27),0),) -> 0 | G28: =IFERROR(IF(D28=$C$7,K27,IF(AND($D$10="Yes",D28<=$C$10),I28,IF(F28>0,$C$8,))),) -> 0 | H28: =IFERROR(IF(B28<$C$9,IF('[29]Proforma-Input'!$C$108="Yes",H27,),0),) -> 0 | I28: =(H28/12)*F28 -> 0 | J28: =IF(D28=$C$7,0,G28-I28) -> 0 | K28: =IFERROR(F28-J28,) -> 0 | L28: =IF(C28>0,SUM(I28:I39),"-") -> 0 | M28: =IF(C28>0,SUM(J28:J39),"-") -> 0 | O28: =IFERROR(DATE(YEAR(O27),MONTH(O27)+1,DAY(O27)),"-") -> 46298 | P28: 2 | Q28: =IF(S28>0,1+Q27,) -> 13 | R28: 1 | S28: =IF('[29]Proforma-Input'!$C$108="No",X27,IF(AF28=TRUE,$P$3,X27)) -> 4944113.7 | T28: =IF(AND($N$8="Yes",Q28<=$P$8),V28,IF(S28>0,$P$7,)) -> 31603.401 | U28: =$P$4 -> 0.065 | V28: =IF(S28>0,U28/12*S28,0) -> 26780.616 | W28: =T28-V28 -> 4822.7852 | X28: =S28-W28 -> 4939290.9 | Y28: =IF(Q28=1,V28,Y27+V28) -> 350135.16 | Z28: =IF(Q28=1,W28,Z27+W28) -> 60709.059 | AA28: =$P$9*S28/12 -> 412.00948 | AB28: =$P$10*AA28 -> 41.200948 | AC28: =IF(P28>0,SUM(V28:V39),"-") -> 319611.73 | AD28: =IF(P28>0,SUM(W28:W39),"-") -> 59629.081 | AF28: =IF('[29]Proforma-Input'!$C$108="Yes",MONTH(O28)&YEAR(O28)=MONTH($C$9)&YEAR($C$9),0) -> 0 | AG28: 2
